Workbook

Sheet 1月台账表
A1: 米油调味品出入库台账
A2: 序号 | B2: 品名 | C2: 单位 | D2: 上月 结存 | E2: 入库 | F2: 出库 | G2: 当前 库存 | H2: 1日 | J2: 2日 | L2: 3日 | N2: 4日 | P2: 5日 | R2: 6日 | T2: 7日 | V2: 8日 | X2: 9日 | Z2: 10日 | AB2: 11日 | AD2: 12日 | AF2: 13日 | AH2: 14日 | AJ2: 15日 | AL2: 16日 | AN2: 17日 | AP2: 18日 | AR2: 19日 | AT2: 20日 | AV2: 21日 | AX2: 22日 | AZ2: 23日 | BB2: 24日 | BD2: 25日 | BF2: 26日 | BH2: 27日 | BJ2: 28日 | BL2: 29日 | BN2: 30日 | BP2: 31日
H3: 46023 | J3: 46024 | L3: 46025 | N3: 46026 | P3: 46027 | R3: 46028 | T3: 46029 | V3: 46030 | X3: 46031 | Z3: 46032 | AB3: 46033 | AD3: 46034 | AF3: 46035 | AH3: 46036 | AJ3: 46037 | AL3: 46038 | AN3: 46039 | AP3: 46040 | AR3: 46041 | AT3: 46042 | AV3: 46043 | AX3: 46044 | AZ3: 46045 | BB3: 46046 | BD3: 46047 | BF3: 46048 | BH3: 46049 | BJ3: 46050 | BL3: 46051 | BN3: 46052 | BP3: 46053
H4: 入库 | I4: 出库 | J4: 入库 | K4: 出库 | L4: 入库 | M4: 出库 | N4: 入库 | O4: 出库 | P4: 入库 | Q4: 出库 | R4: 入库 | S4: 出库 | T4: 入库 | U4: 出库 | V4: 入库 | W4: 出库 | X4: 入库 | Y4: 出库 | Z4: 入库 | AA4: 出库 | AB4: 入库 | AC4: 出库 | AD4: 入库 | AE4: 出库 | AF4: 入库 | AG4: 出库 | AH4: 入库 | AI4: 出库 | AJ4: 入库 | AK4: 出库 | AL4: 入库 | AM4: 出库 | AN4: 入库 | AO4: 出库 | AP4: 入库 | AQ4: 出库 | AR4: 入库 | AS4: 出库 | AT4: 入库 | AU4: 出库 | AV4: 入库 | AW4: 出库 | AX4: 入库 | AY4: 出库 | AZ4: 入库 | BA4: 出库 | BB4: 入库 | BC4: 出库 | BD4: 入库 | BE4: 出库 | BF4: 入库 | BG4: 出库 | BH4: 入库 | BI4: 出库 | BJ4: 入库 | BK4: 出库 | BL4: 入库 | BM4: 出库 | BN4: 入库 | BO4: 出库 | BP4: 入库 | BQ4: 出库
A5: =ROW()-4 -> 1 | B5: 秋然香米10千克/袋 | C5: =IFERROR(VLOOKUP(B5,产品数据!$B:$D,3,FALSE),"") -> 袋 | D5: 22 | E5: =SUMIF($H$4:$BQ$4,$E$2,H5:BQ5) -> 40 | F5: =SUMIF($H$4:$BQ$4,$F$2,H5:BQ5) -> 51 | G5: =D5+E5-F5 -> 11 | H5: =SUMIFS(入库流水账!$E:$E,入库流水账!$C:$C,$B5,入库流水账!$B:$B,H$3) -> 0 | I5: =SUMIFS(出库流水账!$E:$E,出库流水账!$C:$C,$B5,出库流水账!$B:$B,H$3) -> 0 | J5: =SUMIFS(入库流水账!$E:$E,入库流水账!$C:$C,$B5,入库流水账!$B:$B,J$3) -> 0 | K5: =SUMIFS(出库流水账!$E:$E,出库流水账!$C:$C,$B5,出库流水账!$B:$B,J$3) -> 0 | L5: =SUMIFS(入库流水账!$E:$E,入库流水账!$C:$C,$B5,入库流水账!$B:$B,L$3) -> 0 | M5: =SUMIFS(出库流水账!$E:$E,出库流水账!$C:$C,$B5,出库流水账!$B:$B,L$3) -> 0 | N5: =SUMIFS(入库流水账!$E:$E,入库流水账!$C:$C,$B5,入库流水账!$B:$B,N$3) -> 0 | O5: =SUMIFS(出库流水账!$E:$E,出库流水账!$C:$C,$B5,出库流水账!$B:$B,N$3) -> 2 | P5: =SUMIFS(入库流水账!$E:$E,入库流水账!$C:$C,$B5,入库流水账!$B:$B,P$3) -> 0 | Q5: =SUMIFS(出库流水账!$E:$E,出库流水账!$C:$C,$B5,出库流水账!$B:$B,P$3) -> 2 | R5: =SUMIFS(入库流水账!$E:$E,入库流水账!$C:$C,$B5,入库流水账!$B:$B,R$3) -> 0 | S5: =SUMIFS(出库流水账!$E:$E,出库流水账!$C:$C,$B5,出库流水账!$B:$B,R$3) -> 2 | T5: =SUMIFS(入库流水账!$E:$E,入库流水账!$C:$C,$B5,入库流水账!$B:$B,T$3) -> 0 | U5: =SUMIFS(出库流水账!$E:$E,出库流水账!$C:$C,$B5,出库流水账!$B:$B,T$3) -> 2 | V5: =SUMIFS(入库流水账!$E:$E,入库流水账!$C:$C,$B5,入库流水账!$B:$B,V$3) -> 0 | W5: =SUMIFS(出库流水账!$E:$E,出库流水账!$C:$C,$B5,出库流水账!$B:$B,V$3) -> 2 | X5: =SUMIFS(入库流水账!$E:$E,入库流水账!$C:$C,$B5,入库流水账!$B:$B,X$3) -> 0 | Y5: =SUMIFS(出库流水账!$E:$E,出库流水账!$C:$C,$B5,出库流水账!$B:$B,X$3) -> 2 | Z5: =SUMIFS(入库流水账!$E:$E,入库流水账!$C:$C,$B5,入库流水账!$B:$B,Z$3) -> 0 | AA5: =SUMIFS(出库流水账!$E:$E,出库流水账!$C:$C,$B5,出库流水账!$B:$B,Z$3) -> 0 | AB5: =SUMIFS(入库流水账!$E:$E,入库流水账!$C:$C,$B5,入库流水账!$B:$B,AB$3) -> 0 | AC5: =SUMIFS(出库流水账!$E:$E,出库流水账!$C:$C,$B5,出库流水账!$B:$B,AB$3) -> 0 | AD5: =SUMIFS(入库流水账!$E:$E,入库流水账!$C:$C,$B5,入库流水账!$B:$B,AD$3) -> 20 | AE5: =SUMIFS(出库流水账!$E:$E,出库流水账!$C:$C,$B5,出库流水账!$B:$B,AD$3) -> 3 | AF5: =SUMIFS(入库流水账!$E:$E,入库流水账!$C:$C,$B5,入库流水账!$B:$B,AF$3) -> 0 | AG5: =SUMIFS(出库流水账!$E:$E,出库流水账!$C:$C,$B5,出库流水账!$B:$B,AF$3) -> 2 | AH5: =SUMIFS(入库流水账!$E:$E,入库流水账!$C:$C,$B5,入库流水账!$B:$B,AH$3) -> 0 | AI5: =SUMIFS(出库流水账!$E:$E,出库流水账!$C:$C,$B5,出库流水账!$B:$B,AH$3) -> 2 | AJ5: =SUMIFS(入库流水账!$E:$E,入库流水账!$C:$C,$B5,入库流水账!$B:$B,AJ$3) -> 0 | AK5: =SUMIFS(出库流水账!$E:$E,出库流水账!$C:$C,$B5,出库流水账!$B:$B,AJ$3) -> 2 | AL5: =SUMIFS(入库流水账!$E:$E,入库流水账!$C:$C,$B5,入库流水账!$B:$B,AL$3) -> 0 | AM5: =SUMIFS(出库流水账!$E:$E,出库流水账!$C:$C,$B5,出库流水账!$B:$B,AL$3) -> 3 | AN5: =SUMIFS(入库流水账!$E:$E,入库流水账!$C:$C,$B5,入库流水账!$B:$B,AN$3) -> 0 | AO5: =SUMIFS(出库流水账!$E:$E,出库流水账!$C:$C,$B5,出库流水账!$B:$B,AN$3) -> 0 | AP5: =SUMIFS(入库流水账!$E:$E,入库流水账!$C:$C,$B5,入库流水账!$B:$B,AP$3) -> 0 | AQ5: =SUMIFS(出库流水账!$E:$E,出库流水账!$C:$C,$B5,出库流水账!$B:$B,AP$3) -> 0 | AR5: =SUMIFS(入库流水账!$E:$E,入库流水账!$C:$C,$B5,入库流水账!$B:$B,AR$3) -> 0 | AS5: =SUMIFS(出库流水账!$E:$E,出库流水账!$C:$C,$B5,出库流水账!$B:$B,AR$3) -> 3 | AT5: =SUMIFS(入库流水账!$E:$E,入库流水账!$C:$C,$B5,入库流水账!$B:$B,AT$3) -> 0 | AU5: =SUMIFS(出库流水账!$E:$E,出库流水账!$C:$C,$B5,出库流水账!$B:$B,AT$3) -> 3 | AV5: =SUMIFS(入库流水账!$E:$E,入库流水账!$C:$C,$B5,入库流水账!$B:$B,AV$3) -> 0 | AW5: =SUMIFS(出库流水账!$E:$E,出库流水账!$C:$C,$B5,出库流水账!$B:$B,AV$3) -> 2 | AX5: =SUMIFS(入库流水账!$E:$E,入库流水账!$C:$C,$B5,入库流水账!$B:$B,AX$3) -> 0 | AY5: =SUMIFS(出库流水账!$E:$E,出库流水账!$C:$C,$B5,出库流水账!$B:$B,AX$3) -> 3 | AZ5: =SUMIFS(入库流水账!$E:$E,入库流水账!$C:$C,$B5,入库流水账!$B:$B,AZ$3) -> 20 | BA5: =SUMIFS(出库流水账!$E:$E,出库流水账!$C:$C,$B5,出库流水账!$B:$B,AZ$3) -> 3 | BB5: =SUMIFS(入库流水账!$E:$E,入库流水账!$C:$C,$B5,入库流水账!$B:$B,BB$3) -> 0 | BC5: =SUMIFS(出库流水账!$E:$E,出库流水账!$C:$C,$B5,出库流水账!$B:$B,BB$3) -> 0 | BD5: =SUMIFS(入库流水账!$E:$E,入库流水账!$C:$C,$B5,入库流水账!$B:$B,BD$3) -> 0 | BE5: =SUMIFS(出库流水账!$E:$E,出库流水账!$C:$C,$B5,出库流水账!$B:$B,BD$3) -> 0 | BF5: =SUMIFS(入库流水账!$E:$E,入库流水账!$C:$C,$B5,入库流水账!$B:$B,BF$3) -> 0 | BG5: =SUMIFS(出库流水账!$E:$E,出库流水账!$C:$C,$B5,出库流水账!$B:$B,BF$3) -> 3 | BH5: =SUMIFS(入库流水账!$E:$E,入库流水账!$C:$C,$B5,入库流水账!$B:$B,BH$3) -> 0 | BI5: =SUMIFS(出库流水账!$E:$E,出库流水账!$C:$C,$B5,出库流水账!$B:$B,BH$3) -> 2 | BJ5: =SUMIFS(入库流水账!$E:$E,入库流水账!$C:$C,$B5,入库流水账!$B:$B,BJ$3) -> 0 | BK5: =SUMIFS(出库流水账!$E:$E,出库流水账!$C:$C,$B5,出库流水账!$B:$B,BJ$3) -> 2 | BL5: =SUMIFS(入库流水账!$E:$E,入库流水账!$C:$C,$B5,入库流水账!$B:$B,BL$3) -> 0 | BM5: =SUMIFS(出库流水账!$E:$E,出库流水账!$C:$C,$B5,出库流水账!$B:$B,BL$3) -> 2 | BN5: =SUMIFS(入库流水账!$E:$E,入库流水账!$C:$C,$B5,入库流水账!$B:$B,BN$3) -> 0 | BO5: =SUMIFS(出库流水账!$E:$E,出库流水账!$C:$C,$B5,出库流水账!$B:$B,BN$3) -> 4 | BP5: =SUMIFS(入库流水账!$E:$E,入库流水账!$C:$C,$B5,入库流水账!$B:$B,BP$3) -> 0 | BQ5: =SUMIFS(出库流水账!$E:$E,出库流水账!$C:$C,$B5,出库流水账!$B:$B,BP$3) -> 0
A6: =ROW()-4 -> 2 | B6: 兆丰雪花粉 | C6: =IFERROR(VLOOKUP(B6,产品数据!$B:$D,3,FALSE),"") -> 包 | D6: 12 | E6: =SUMIF($H$4:$BQ$4,$E$2,H6:BQ6) -> 48 | F6: =SUMIF($H$4:$BQ$4,$F$2,H6:BQ6) -> 30 | G6: =D6+E6-F6 -> 30 | H6: =SUMIFS(入库流水账!$E:$E,入库流水账!$C:$C,$B6,入库流水账!$B:$B,H$3) -> 0 | I6: =SUMIFS(出库流水账!$E:$E,出库流水账!$C:$C,$B6,出库流水账!$B:$B,H$3) -> 0 | J6: =SUMIFS(入库流水账!$E:$E,入库流水账!$C:$C,$B6,入库流水账!$B:$B,J$3) -> 0 | K6: =SUMIFS(出库流水账!$E:$E,出库流水账!$C:$C,$B6,出库流水账!$B:$B,J$3) -> 0 | L6: =SUMIFS(入库流水账!$E:$E,入库流水账!$C:$C,$B6,入库流水账!$B:$B,L$3) -> 0 | M6: =SUMIFS(出库流水账!$E:$E,出库流水账!$C:$C,$B6,出库流水账!$B:$B,L$3) -> 0 | N6: =SUMIFS(入库流水账!$E:$E,入库流水账!$C:$C,$B6,入库流水账!$B:$B,N$3) -> 0 | O6: =SUMIFS(出库流水账!$E:$E,出库流水账!$C:$C,$B6,出库流水账!$B:$B,N$3) -> 3 | P6: =SUMIFS(入库流水账!$E:$E,入库流水账!$C:$C,$B6,入库流水账!$B:$B,P$3) -> 0 | Q6: =SUMIFS(出库流水账!$E:$E,出库流水账!$C:$C,$B6,出库流水账!$B:$B,P$3) -> 3 | R6: =SUMIFS(入库流水账!$E:$E,入库流水账!$C:$C,$B6,入库流水账!$B:$B,R$3) -> 0 | S6: =SUMIFS(出库流水账!$E:$E,出库流水账!$C:$C,$B6,出库流水账!$B:$B,R$3) -> 0 | T6: =SUMIFS(入库流水账!$E:$E,入库流水账!$C:$C,$B6,入库流水账!$B:$B,T$3) -> 0 | U6: =SUMIFS(出库流水账!$E:$E,出库流水账!$C:$C,$B6,出库流水账!$B:$B,T$3) -> 3 | V6: =SUMIFS(入库流水账!$E:$E,入库流水账!$C:$C,$B6,入库流水账!$B:$B,V$3) -> 12 | W6: =SUMIFS(出库流水账!$E:$E,出库流水账!$C:$C,$B6,出库流水账!$B:$B,V$3) -> 0 | X6: =SUMIFS(入库流水账!$E:$E,入库流水账!$C:$C,$B6,入库流水账!$B:$B,X$3) -> 0 | Y6: =SUMIFS(出库流水账!$E:$E,出库流水账!$C:$C,$B6,出库流水账!$B:$B,X$3) -> 0 | Z6: =SUMIFS(入库流水账!$E:$E,入库流水账!$C:$C,$B6,入库流水账!$B:$B,Z$3) -> 0 | AA6: =SUMIFS(出库流水账!$E:$E,出库流水账!$C:$C,$B6,出库流水账!$B:$B,Z$3) -> 0 | AB6: =SUMIFS(入库流水账!$E:$E,入库流水账!$C:$C,$B6,入库流水账!$B:$B,AB$3) -> 0 | AC6: =SUMIFS(出库流水账!$E:$E,出库流水账!$C:$C,$B6,出库流水账!$B:$B,AB$3) -> 0 | AD6: =SUMIFS(入库流水账!$E:$E,入库流水账!$C:$C,$B6,入库流水账!$B:$B,AD$3) -> 0 | AE6: =SUMIFS(出库流水账!$E:$E,出库流水账!$C:$C,$B6,出库流水账!$B:$B,AD$3) -> 3 | AF6: =SUMIFS(入库流水账!$E:$E,入库流水账!$C:$C,$B6,入库流水账!$B:$B,AF$3) -> 0 | AG6: =SUMIFS(出库流水账!$E:$E,出库流水账!$C:$C,$B6,出库流水账!$B:$B,AF$3) -> 0 | AH6: =SUMIFS(入库流水账!$E:$E,入库流水账!$C:$C,$B6,入库流水账!$B:$B,AH$3) -> 0 | AI6: =SUMIFS(出库流水账!$E:$E,出库流水账!$C:$C,$B6,出库流水账!$B:$B,AH$3) -> 0 | AJ6: =SUMIFS(入库流水账!$E:$E,入库流水账!$C:$C,$B6,入库流水账!$B:$B,AJ$3) -> 0 | AK6: =SUMIFS(出库流水账!$E:$E,出库流水账!$C:$C,$B6,出库流水账!$B:$B,AJ$3) -> 1 | AL6: =SUMIFS(入库流水账!$E:$E,入库流水账!$C:$C,$B6,入库流水账!$B:$B,AL$3) -> 0 | AM6: =SUMIFS(出库流水账!$E:$E,出库流水账!$C:$C,$B6,出库流水账!$B:$B,AL$3) -> 0 | AN6: =SUMIFS(入库流水账!$E:$E,入库流水账!$C:$C,$B6,入库流水账!$B:$B,AN$3) -> 0 | AO6: =SUMIFS(出库流水账!$E:$E,出库流水账!$C:$C,$B6,出库流水账!$B:$B,AN$3) -> 0 | AP6: =SUMIFS(入库流水账!$E:$E,入库流水账!$C:$C,$B6,入库流水账!$B:$B,AP$3) -> 0 | AQ6: =SUMIFS(出库流水账!$E:$E,出库流水账!$C:$C,$B6,出库流水账!$B:$B,AP$3) -> 0 | AR6: =SUMIFS(入库流水账!$E:$E,入库流水账!$C:$C,$B6,入库流水账!$B:$B,AR$3) -> 0 | AS6: =SUMIFS(出库流水账!$E:$E,出库流水账!$C:$C,$B6,出库流水账!$B:$B,AR$3) -> 5 | AT6: =SUMIFS(入库流水账!$E:$E,入库流水账!$C:$C,$B6,入库流水账!$B:$B,AT$3) -> 0 | AU6: =SUMIFS(出库流水账!$E:$E,出库流水账!$C:$C,$B6,出库流水账!$B:$B,AT$3) -> 0 | AV6: =SUMIFS(入库流水账!$E:$E,入库流水账!$C:$C,$B6,入库流水账!$B:$B,AV$3) -> 0 | AW6: =SUMIFS(出库流水账!$E:$E,出库流水账!$C:$C,$B6,出库流水账!$B:$B,AV$3) -> 0 | AX6: =SUMIFS(入库流水账!$E:$E,入库流水账!$C:$C,$B6,入库流水账!$B:$B,AX$3) -> 0 | AY6: =SUMIFS(出库流水账!$E:$E,出库流水账!$C:$C,$B6,出库流水账!$B:$B,AX$3) -> 4 | AZ6: =SUMIFS(入库流水账!$E:$E,入库流水账!$C:$C,$B6,入库流水账!$B:$B,AZ$3) -> 27 | BA6: =SUMIFS(出库流水账!$E:$E,出库流水账!$C:$C,$B6,出库流水账!$B:$B,AZ$3) -> 0 | BB6: =SUMIFS(入库流水账!$E:$E,入库流水账!$C:$C,$B6,入库流水账!$B:$B,BB$3) -> 0 | BC6: =SUMIFS(出库流水账!$E:$E,出库流水账!$C:$C,$B6,出库流水账!$B:$B,BB$3) -> 0 | BD6: =SUMIFS(入库流水账!$E:$E,入库流水账!$C:$C,$B6,入库流水账!$B:$B,BD$3) -> 0 | BE6: =SUMIFS(出库流水账!$E:$E,出库流水账!$C:$C,$B6,出库流水账!$B:$B,BD$3) -> 0 | BF6: =SUMIFS(入库流水账!$E:$E,入库流水账!$C:$C,$B6,入库流水账!$B:$B,BF$3) -> 0 | BG6: =SUMIFS(出库流水账!$E:$E,出库流水账!$C:$C,$B6,出库流水账!$B:$B,BF$3) -> 3 | BH6: =SUMIFS(入库流水账!$E:$E,入库流水账!$C:$C,$B6,入库流水账!$B:$B,BH$3) -> 9 | BI6: =SUMIFS(出库流水账!$E:$E,出库流水账!$C:$C,$B6,出库流水账!$B:$B,BH$3) -> 3 | BJ6: =SUMIFS(入库流水账!$E:$E,入库流水账!$C:$C,$B6,入库流水账!$B:$B,BJ$3) -> 0 | BK6: =SUMIFS(出库流水账!$E:$E,出库流水账!$C:$C,$B6,出库流水账!$B:$B,BJ$3) -> 1 | BL6: =SUMIFS(入库流水账!$E:$E,入库流水账!$C:$C,$B6,入库流水账!$B:$B,BL$3) -> 0 | BM6: =SUMIFS(出库流水账!$E:$E,出库流水账!$C:$C,$B6,出库流水账!$B:$B,BL$3) -> 1 | BN6: =SUMIFS(入库流水账!$E:$E,入库流水账!$C:$C,$B6,入库流水账!$B:$B,BN$3) -> 0 | BO6: =SUMIFS(出库流水账!$E:$E,出库流水账!$C:$C,$B6,出库流水账!$B:$B,BN$3) -> 0 | BP6: =SUMIFS(入库流水账!$E:$E,入库流水账!$C:$C,$B6,入库流水账!$B:$B,BP$3) -> 0 | BQ6: =SUMIFS(出库流水账!$E:$E,出库流水账!$C:$C,$B6,出库流水账!$B:$B,BP$3) -> 0
A7: =ROW()-4 -> 3 | B7: 鲁花压榨特香玉米胚芽油5升/桶*4/箱 | C7: =IFERROR(VLOOKUP(B7,产品数据!$B:$D,3,FALSE),"") -> 桶 | D7: 22 | E7: =SUMIF($H$4:$BQ$4,$E$2,H7:BQ7) -> 80 | F7: =SUMIF($H$4:$BQ$4,$F$2,H7:BQ7) -> 83 | G7: =D7+E7-F7 -> 19 | H7: =SUMIFS(入库流水账!$E:$E,入库流水账!$C:$C,$B7,入库流水账!$B:$B,H$3) -> 0 | I7: =SUMIFS(出库流水账!$E:$E,出库流水账!$C:$C,$B7,出库流水账!$B:$B,H$3) -> 0 | J7: =SUMIFS(入库流水账!$E:$E,入库流水账!$C:$C,$B7,入库流水账!$B:$B,J$3) -> 0 | K7: =SUMIFS(出库流水账!$E:$E,出库流水账!$C:$C,$B7,出库流水账!$B:$B,J$3) -> 0 | L7: =SUMIFS(入库流水账!$E:$E,入库流水账!$C:$C,$B7,入库流水账!$B:$B,L$3) -> 0 | M7: =SUMIFS(出库流水账!$E:$E,出库流水账!$C:$C,$B7,出库流水账!$B:$B,L$3) -> 0 | N7: =SUMIFS(入库流水账!$E:$E,入库流水账!$C:$C,$B7,入库流水账!$B:$B,N$3) -> 0 | O7: =SUMIFS(出库流水账!$E:$E,出库流水账!$C:$C,$B7,出库流水账!$B:$B,N$3) -> 6 | P7: =SUMIFS(入库流水账!$E:$E,入库流水账!$C:$C,$B7,入库流水账!$B:$B,P$3) -> 0 | Q7: =SUMIFS(出库流水账!$E:$E,出库流水账!$C:$C,$B7,出库流水账!$B:$B,P$3) -> 3 | R7: =SUMIFS(入库流水账!$E:$E,入库流水账!$C:$C,$B7,入库流水账!$B:$B,R$3) -> 0 | S7: =SUMIFS(出库流水账!$E:$E,出库流水账!$C:$C,$B7,出库流水账!$B:$B,R$3) -> 3 | T7: =SUMIFS(入库流水账!$E:$E,入库流水账!$C:$C,$B7,入库流水账!$B:$B,T$3) -> 20 | U7: =SUMIFS(出库流水账!$E:$E,出库流水账!$C:$C,$B7,出库流水账!$B:$B,T$3) -> 3 | V7: =SUMIFS(入库流水账!$E:$E,入库流水账!$C:$C,$B7,入库流水账!$B:$B,V$3) -> 0 | W7: =SUMIFS(出库流水账!$E:$E,出库流水账!$C:$C,$B7,出库流水账!$B:$B,V$3) -> 4 | X7: =SUMIFS(入库流水账!$E:$E,入库流水账!$C:$C,$B7,入库流水账!$B:$B,X$3) -> 0 | Y7: =SUMIFS(出库流水账!$E:$E,出库流水账!$C:$C,$B7,出库流水账!$B:$B,X$3) -> 5 | Z7: =SUMIFS(入库流水账!$E:$E,入库流水账!$C:$C,$B7,入库流水账!$B:$B,Z$3) -> 0 | AA7: =SUMIFS(出库流水账!$E:$E,出库流水账!$C:$C,$B7,出库流水账!$B:$B,Z$3) -> 0 | AB7: =SUMIFS(入库流水账!$E:$E,入库流水账!$C:$C,$B7,入库流水账!$B:$B,AB$3) -> 0 | AC7: =SUMIFS(出库流水账!$E:$E,出库流水账!$C:$C,$B7,出库流水账!$B:$B,AB$3) -> 0 | AD7: =SUMIFS(入库流水账!$E:$E,入库流水账!$C:$C,$B7,入库流水账!$B:$B,AD$3) -> 0 | AE7: =SUMIFS(出库流水账!$E:$E,出库流水账!$C:$C,$B7,出库流水账!$B:$B,AD$3) -> 4 | AF7: =SUMIFS(入库流水账!$E:$E,入库流水账!$C:$C,$B7,入库流水账!$B:$B,AF$3) -> 0 | AG7: =SUMIFS(出库流水账!$E:$E,出库流水账!$C:$C,$B7,出库流水账!$B:$B,AF$3) -> 3 | AH7: =SUMIFS(入库流水账!$E:$E,入库流水账!$C:$C,$B7,入库流水账!$B:$B,AH$3) -> 0 | AI7: =SUMIFS(出库流水账!$E:$E,出库流水账!$C:$C,$B7,出库流水账!$B:$B,AH$3) -> 4 | AJ7: =SUMIFS(入库流水账!$E:$E,入库流水账!$C:$C,$B7,入库流水账!$B:$B,AJ$3) -> 20 | AK7: =SUMIFS(出库流水账!$E:$E,出库流水账!$C:$C,$B7,出库流水账!$B:$B,AJ$3) -> 3 | AL7: =SUMIFS(入库流水账!$E:$E,入库流水账!$C:$C,$B7,入库流水账!$B:$B,AL$3) -> 0 | AM7: =SUMIFS(出库流水账!$E:$E,出库流水账!$C:$C,$B7,出库流水账!$B:$B,AL$3) -> 4 | AN7: =SUMIFS(入库流水账!$E:$E,入库流水账!$C:$C,$B7,入库流水账!$B:$B,AN$3) -> 0 | AO7: =SUMIFS(出库流水账!$E:$E,出库流水账!$C:$C,$B7,出库流水账!$B:$B,AN$3) -> 0 | AP7: =SUMIFS(入库流水账!$E:$E,入库流水账!$C:$C,$B7,入库流水账!$B:$B,AP$3) -> 0 | AQ7: =SUMIFS(出库流水账!$E:$E,出库流水账!$C:$C,$B7,出库流水账!$B:$B,AP$3) -> 0 | AR7: =SUMIFS(入库流水账!$E:$E,入库流水账!$C:$C,$B7,入库流水账!$B:$B,AR$3) -> 0 | AS7: =SUMIFS(出库流水账!$E:$E,出库流水账!$C:$C,$B7,出库流水账!$B:$B,AR$3) -> 4 | AT7: =SUMIFS(入库流水账!$E:$E,入库流水账!$C:$C,$B7,入库流水账!$B:$B,AT$3) -> 20 | AU7: =SUMIFS(出库流水账!$E:$E,出库流水账!$C:$C,$B7,出库流水账!$B:$B,AT$3) -> 4 | AV7: =SUMIFS(入库流水账!$E:$E,入库流水账!$C:$C,$B7,入库流水账!$B:$B,AV$3) -> 0 | AW7: =SUMIFS(出库流水账!$E:$E,出库流水账!$C:$C,$B7,出库流水账!$B:$B,AV$3) -> 3 | AX7: =SUMIFS(入库流水账!$E:$E,入库流水账!$C:$C,$B7,入库流水账!$B:$B,AX$3) -> 0 | AY7: =SUMIFS(出库流水账!$E:$E,出库流水账!$C:$C,$B7,出库流水账!$B:$B,AX$3) -> 3 | AZ7: =SUMIFS(入库流水账!$E:$E,入库流水账!$C:$C,$B7,入库流水账!$B:$B,AZ$3) -> 20 | BA7: =SUMIFS(出库流水账!$E:$E,出库流水账!$C:$C,$B7,出库流水账!$B:$B,AZ$3) -> 4 | BB7: =SUMIFS(入库流水账!$E:$E,入库流水账!$C:$C,$B7,入库流水账!$B:$B,BB$3) -> 0 | BC7: =SUMIFS(出库流水账!$E:$E,出库流水账!$C:$C,$B7,出库流水账!$B:$B,BB$3) -> 0 | BD7: =SUMIFS(入库流水账!$E:$E,入库流水账!$C:$C,$B7,入库流水账!$B:$B,BD$3) -> 0 | BE7: =SUMIFS(出库流水账!$E:$E,出库流水账!$C:$C,$B7,出库流水账!$B:$B,BD$3) -> 0 | BF7: =SUMIFS(入库流水账!$E:$E,入库流水账!$C:$C,$B7,入库流水账!$B:$B,BF$3) -> 0 | BG7: =SUMIFS(出库流水账!$E:$E,出库流水账!$C:$C,$B7,出库流水账!$B:$B,BF$3) -> 6 | BH7: =SUMIFS(入库流水账!$E:$E,入库流水账!$C:$C,$B7,入库流水账!$B:$B,BH$3) -> 0 | BI7: =SUMIFS(出库流水账!$E:$E,出库流水账!$C:$C,$B7,出库流水账!$B:$B,BH$3) -> 3 | BJ7: =SUMIFS(入库流水账!$E:$E,入库流水账!$C:$C,$B7,入库流水账!$B:$B,BJ$3) -> 0 | BK7: =SUMIFS(出库流水账!$E:$E,出库流水账!$C:$C,$B7,出库流水账!$B:$B,BJ$3) -> 3 | BL7: =SUMIFS(入库流水账!$E:$E,入库流水账!$C:$C,$B7,入库流水账!$B:$B,BL$3) -> 0 | BM7: =SUMIFS(出库流水账!$E:$E,出库流水账!$C:$C,$B7,出库流水账!$B:$B,BL$3) -> 4 | BN7: =SUMIFS(入库流水账!$E:$E,入库流水账!$C:$C,$B7,入库流水账!$B:$B,BN$3) -> 0 | BO7: =SUMIFS(出库流水账!$E:$E,出库流水账!$C:$C,$B7,出库流水账!$B:$B,BN$3) -> 7 | BP7: =SUMIFS(入库流水账!$E:$E,入库流水账!$C:$C,$B7,入库流水账!$B:$B,BP$3) -> 0 | BQ7: =SUMIFS(出库流水账!$E:$E,出库流水账!$C:$C,$B7,出库流水账!$B:$B,BP$3) -> 0
A8: =ROW()-4 -> 4 | B8: 厨邦美味鲜酱油 | C8: =IFERROR(VLOOKUP(B8,产品数据!$B:$D,3,FALSE),"") -> 壶 | D8: 6 | E8: =SUMIF($H$4:$BQ$4,$E$2,H8:BQ8) -> 36 | F8: =SUMIF($H$4:$BQ$4,$F$2,H8:BQ8) -> 28 | G8: =D8+E8-F8 -> 14 | H8: =SUMIFS(入库流水账!$E:$E,入库流水账!$C:$C,$B8,入库流水账!$B:$B,H$3) -> 0 | I8: =SUMIFS(出库流水账!$E:$E,出库流水账!$C:$C,$B8,出库流水账!$B:$B,H$3) -> 0 | J8: =SUMIFS(入库流水账!$E:$E,入库流水账!$C:$C,$B8,入库流水账!$B:$B,J$3) -> 0 | K8: =SUMIFS(出库流水账!$E:$E,出库流水账!$C:$C,$B8,出库流水账!$B:$B,J$3) -> 0 | L8: =SUMIFS(入库流水账!$E:$E,入库流水账!$C:$C,$B8,入库流水账!$B:$B,L$3) -> 0 | M8: =SUMIFS(出库流水账!$E:$E,出库流水账!$C:$C,$B8,出库流水账!$B:$B,L$3) -> 0 | N8: =SUMIFS(入库流水账!$E:$E,入库流水账!$C:$C,$B8,入库流水账!$B:$B,N$3) -> 0 | O8: =SUMIFS(出库流水账!$E:$E,出库流水账!$C:$C,$B8,出库流水账!$B:$B,N$3) -> 2 | P8: =SUMIFS(入库流水账!$E:$E,入库流水账!$C:$C,$B8,入库流水账!$B:$B,P$3) -> 0 | Q8: =SUMIFS(出库流水账!$E:$E,出库流水账!$C:$C,$B8,出库流水账!$B:$B,P$3) -> 0 | R8: =SUMIFS(入库流水账!$E:$E,入库流水账!$C:$C,$B8,入库流水账!$B:$B,R$3) -> 0 | S8: =SUMIFS(出库流水账!$E:$E,出库流水账!$C:$C,$B8,出库流水账!$B:$B,R$3) -> 2 | T8: =SUMIFS(入库流水账!$E:$E,入库流水账!$C:$C,$B8,入库流水账!$B:$B,T$3) -> 18 | U8: =SUMIFS(出库流水账!$E:$E,出库流水账!$C:$C,$B8,出库流水账!$B:$B,T$3) -> 0 | V8: =SUMIFS(入库流水账!$E:$E,入库流水账!$C:$C,$B8,入库流水账!$B:$B,V$3) -> 0 | W8: =SUMIFS(出库流水账!$E:$E,出库流水账!$C:$C,$B8,出库流水账!$B:$B,V$3) -> 1 | X8: =SUMIFS(入库流水账!$E:$E,入库流水账!$C:$C,$B8,入库流水账!$B:$B,X$3) -> 0 | Y8: =SUMIFS(出库流水账!$E:$E,出库流水账!$C:$C,$B8,出库流水账!$B:$B,X$3) -> 1 | Z8: =SUMIFS(入库流水账!$E:$E,入库流水账!$C:$C,$B8,入库流水账!$B:$B,Z$3) -> 0 | AA8: =SUMIFS(出库流水账!$E:$E,出库流水账!$C:$C,$B8,出库流水账!$B:$B,Z$3) -> 0 | AB8: =SUMIFS(入库流水账!$E:$E,入库流水账!$C:$C,$B8,入库流水账!$B:$B,AB$3) -> 0 | AC8: =SUMIFS(出库流水账!$E:$E,出库流水账!$C:$C,$B8,出库流水账!$B:$B,AB$3) -> 0 | AD8: =SUMIFS(入库流水账!$E:$E,入库流水账!$C:$C,$B8,入库流水账!$B:$B,AD$3) -> 0 | AE8: =SUMIFS(出库流水账!$E:$E,出库流水账!$C:$C,$B8,出库流水账!$B:$B,AD$3) -> 3 | AF8: =SUMIFS(入库流水账!$E:$E,入库流水账!$C:$C,$B8,入库流水账!$B:$B,AF$3) -> 0 | AG8: =SUMIFS(出库流水账!$E:$E,出库流水账!$C:$C,$B8,出库流水账!$B:$B,AF$3) -> 1 | AH8: =SUMIFS(入库流水账!$E:$E,入库流水账!$C:$C,$B8,入库流水账!$B:$B,AH$3) -> 0 | AI8: =SUMIFS(出库流水账!$E:$E,出库流水账!$C:$C,$B8,出库流水账!$B:$B,AH$3) -> 1 | AJ8: =SUMIFS(入库流水账!$E:$E,入库流水账!$C:$C,$B8,入库流水账!$B:$B,AJ$3) -> 0 | AK8: =SUMIFS(出库流水账!$E:$E,出库流水账!$C:$C,$B8,出库流水账!$B:$B,AJ$3) -> 1 | AL8: =SUMIFS(入库流水账!$E:$E,入库流水账!$C:$C,$B8,入库流水账!$B:$B,AL$3) -> 0 | AM8: =SUMIFS(出库流水账!$E:$E,出库流水账!$C:$C,$B8,出库流水账!$B:$B,AL$3) -> 2 | AN8: =SUMIFS(入库流水账!$E:$E,入库流水账!$C:$C,$B8,入库流水账!$B:$B,AN$3) -> 0 | AO8: =SUMIFS(出库流水账!$E:$E,出库流水账!$C:$C,$B8,出库流水账!$B:$B,AN$3) -> 0 | AP8: =SUMIFS(入库流水账!$E:$E,入库流水账!$C:$C,$B8,入库流水账!$B:$B,AP$3) -> 0 | AQ8: =SUMIFS(出库流水账!$E:$E,出库流水账!$C:$C,$B8,出库流水账!$B:$B,AP$3) -> 0 | AR8: =SUMIFS(入库流水账!$E:$E,入库流水账!$C:$C,$B8,入库流水账!$B:$B,AR$3) -> 0 | AS8: =SUMIFS(出库流水账!$E:$E,出库流水账!$C:$C,$B8,出库流水账!$B:$B,AR$3) -> 2 | AT8: =SUMIFS(入库流水账!$E:$E,入库流水账!$C:$C,$B8,入库流水账!$B:$B,AT$3) -> 0 | AU8: =SUMIFS(出库流水账!$E:$E,出库流水账!$C:$C,$B8,出库流水账!$B:$B,AT$3) -> 1 | AV8: =SUMIFS(入库流水账!$E:$E,入库流水账!$C:$C,$B8,入库流水账!$B:$B,AV$3) -> 0 | AW8: =SUMIFS(出库流水账!$E:$E,出库流水账!$C:$C,$B8,出库流水账!$B:$B,AV$3) -> 1 | AX8: =SUMIFS(入库流水账!$E:$E,入库流水账!$C:$C,$B8,入库流水账!$B:$B,AX$3) -> 0 | AY8: =SUMIFS(出库流水账!$E:$E,出库流水账!$C:$C,$B8,出库流水账!$B:$B,AX$3) -> 0 | AZ8: =SUMIFS(入库流水账!$E:$E,入库流水账!$C:$C,$B8,入库流水账!$B:$B,AZ$3) -> 18 | BA8: =SUMIFS(出库流水账!$E:$E,出库流水账!$C:$C,$B8,出库流水账!$B:$B,AZ$3) -> 2 | BB8: =SUMIFS(入库流水账!$E:$E,入库流水账!$C:$C,$B8,入库流水账!$B:$B,BB$3) -> 0 | BC8: =SUMIFS(出库流水账!$E:$E,出库流水账!$C:$C,$B8,出库流水账!$B:$B,BB$3) -> 0 | BD8: =SUMIFS(入库流水账!$E:$E,入库流水账!$C:$C,$B8,入库流水账!$B:$B,BD$3) -> 0 | BE8: =SUMIFS(出库流水账!$E:$E,出库流水账!$C:$C,$B8,出库流水账!$B:$B,BD$3) -> 0 | BF8: =SUMIFS(入库流水账!$E:$E,入库流水账!$C:$C,$B8,入库流水账!$B:$B,BF$3) -> 0 | BG8: =SUMIFS(出库流水账!$E:$E,出库流水账!$C:$C,$B8,出库流水账!$B:$B,BF$3) -> 2 | BH8: =SUMIFS(入库流水账!$E:$E,入库流水账!$C:$C,$B8,入库流水账!$B:$B,BH$3) -> 0 | BI8: =SUMIFS(出库流水账!$E:$E,出库流水账!$C:$C,$B8,出库流水账!$B:$B,BH$3) -> 2 | BJ8: =SUMIFS(入库流水账!$E:$E,入库流水账!$C:$C,$B8,入库流水账!$B:$B,BJ$3) -> 0 | BK8: =SUMIFS(出库流水账!$E:$E,出库流水账!$C:$C,$B8,出库流水账!$B:$B,BJ$3) -> 1 | BL8: =SUMIFS(入库流水账!$E:$E,入库流水账!$C:$C,$B8,入库流水账!$B:$B,BL$3) -> 0 | BM8: =SUMIFS(出库流水账!$E:$E,出库流水账!$C:$C,$B8,出库流水账!$B:$B,BL$3) -> 1 | BN8: =SUMIFS(入库流水账!$E:$E,入库流水账!$C:$C,$B8,入库流水账!$B:$B,BN$3) -> 0 | BO8: =SUMIFS(出库流水账!$E:$E,出库流水账!$C:$C,$B8,出库流水账!$B:$B,BN$3) -> 2 | BP8: =SUMIFS(入库流水账!$E:$E,入库流水账!$C:$C,$B8,入库流水账!$B:$B,BP$3) -> 0 | BQ8: =SUMIFS(出库流水账!$E:$E,出库流水账!$C:$C,$B8,出库流水账!$B:$B,BP$3) -> 0
A9: =ROW()-4 -> 5 | B9: 海天老抽酱油 | C9: =IFERROR(VLOOKUP(B9,产品数据!$B:$D,3,FALSE),"") -> 瓶 | D9: ='[2]米油调味品台账表 12月 '!G10 -> 2 | E9: =SUMIF($H$4:$BQ$4,$E$2,H9:BQ9) -> 24 | F9: =SUMIF($H$4:$BQ$4,$F$2,H9:BQ9) -> 15 | G9: =D9+E9-F9 -> 11 | H9: =SUMIFS(入库流水账!$E:$E,入库流水账!$C:$C,$B9,入库流水账!$B:$B,H$3) -> 0 | I9: =SUMIFS(出库流水账!$E:$E,出库流水账!$C:$C,$B9,出库流水账!$B:$B,H$3) -> 0 | J9: =SUMIFS(入库流水账!$E:$E,入库流水账!$C:$C,$B9,入库流水账!$B:$B,J$3) -> 0 | K9: =SUMIFS(出库流水账!$E:$E,出库流水账!$C:$C,$B9,出库流水账!$B:$B,J$3) -> 0 | L9: =SUMIFS(入库流水账!$E:$E,入库流水账!$C:$C,$B9,入库流水账!$B:$B,L$3) -> 0 | M9: =SUMIFS(出库流水账!$E:$E,出库流水账!$C:$C,$B9,出库流水账!$B:$B,L$3) -> 0 | N9: =SUMIFS(入库流水账!$E:$E,入库流水账!$C:$C,$B9,入库流水账!$B:$B,N$3) -> 0 | O9: =SUMIFS(出库流水账!$E:$E,出库流水账!$C:$C,$B9,出库流水账!$B:$B,N$3) -> 0 | P9: =SUMIFS(入库流水账!$E:$E,入库流水账!$C:$C,$B9,入库流水账!$B:$B,P$3) -> 0 | Q9: =SUMIFS(出库流水账!$E:$E,出库流水账!$C:$C,$B9,出库流水账!$B:$B,P$3) -> 1 | R9: =SUMIFS(入库流水账!$E:$E,入库流水账!$C:$C,$B9,入库流水账!$B:$B,R$3) -> 0 | S9: =SUMIFS(出库流水账!$E:$E,出库流水账!$C:$C,$B9,出库流水账!$B:$B,R$3) -> 0 | T9: =SUMIFS(入库流水账!$E:$E,入库流水账!$C:$C,$B9,入库流水账!$B:$B,T$3) -> 6 | U9: =SUMIFS(出库流水账!$E:$E,出库流水账!$C:$C,$B9,出库流水账!$B:$B,T$3) -> 1 | V9: =SUMIFS(入库流水账!$E:$E,入库流水账!$C:$C,$B9,入库流水账!$B:$B,V$3) -> 0 | W9: =SUMIFS(出库流水账!$E:$E,出库流水账!$C:$C,$B9,出库流水账!$B:$B,V$3) -> 0 | X9: =SUMIFS(入库流水账!$E:$E,入库流水账!$C:$C,$B9,入库流水账!$B:$B,X$3) -> 0 | Y9: =SUMIFS(出库流水账!$E:$E,出库流水账!$C:$C,$B9,出库流水账!$B:$B,X$3) -> 1 | Z9: =SUMIFS(入库流水账!$E:$E,入库流水账!$C:$C,$B9,入库流水账!$B:$B,Z$3) -> 0 | AA9: =SUMIFS(出库流水账!$E:$E,出库流水账!$C:$C,$B9,出库流水账!$B:$B,Z$3) -> 0 | AB9: =SUMIFS(入库流水账!$E:$E,入库流水账!$C:$C,$B9,入库流水账!$B:$B,AB$3) -> 0 | AC9: =SUMIFS(出库流水账!$E:$E,出库流水账!$C:$C,$B9,出库流水账!$B:$B,AB$3) -> 0 | AD9: =SUMIFS(入库流水账!$E:$E,入库流水账!$C:$C,$B9,入库流水账!$B:$B,AD$3) -> 0 | AE9: =SUMIFS(出库流水账!$E:$E,出库流水账!$C:$C,$B9,出库流水账!$B:$B,AD$3) -> 2 | AF9: =SUMIFS(入库流水账!$E:$E,入库流水账!$C:$C,$B9,入库流水账!$B:$B,AF$3) -> 0 | AG9: =SUMIFS(出库流水账!$E:$E,出库流水账!$C:$C,$B9,出库流水账!$B:$B,AF$3) -> 0 | AH9: =SUMIFS(入库流水账!$E:$E,入库流水账!$C:$C,$B9,入库流水账!$B:$B,AH$3) -> 0 | AI9: =SUMIFS(出库流水账!$E:$E,出库流水账!$C:$C,$B9,出库流水账!$B:$B,AH$3) -> 0 | AJ9: =SUMIFS(入库流水账!$E:$E,入库流水账!$C:$C,$B9,入库流水账!$B:$B,AJ$3) -> 0 | AK9: =SUMIFS(出库流水账!$E:$E,出库流水账!$C:$C,$B9,出库流水账!$B:$B,AJ$3) -> 1 | AL9: =SUMIFS(入库流水账!$E:$E,入库流水账!$C:$C,$B9,入库流水账!$B:$B,AL$3) -> 0 | AM9: =SUMIFS(出库流水账!$E:$E,出库流水账!$C:$C,$B9,出库流水账!$B:$B,AL$3) -> 1 | AN9: =SUMIFS(入库流水账!$E:$E,入库流水账!$C:$C,$B9,入库流水账!$B:$B,AN$3) -> 0 | AO9: =SUMIFS(出库流水账!$E:$E,出库流水账!$C:$C,$B9,出库流水账!$B:$B,AN$3) -> 0 | AP9: =SUMIFS(入库流水账!$E:$E,入库流水账!$C:$C,$B9,入库流水账!$B:$B,AP$3) -> 0 | AQ9: =SUMIFS(出库流水账!$E:$E,出库流水账!$C:$C,$B9,出库流水账!$B:$B,AP$3) -> 0 | AR9: =SUMIFS(入库流水账!$E:$E,入库流水账!$C:$C,$B9,入库流水账!$B:$B,AR$3) -> 0 | AS9: =SUMIFS(出库流水账!$E:$E,出库流水账!$C:$C,$B9,出库流水账!$B:$B,AR$3) -> 2 | AT9: =SUMIFS(入库流水账!$E:$E,入库流水账!$C:$C,$B9,入库流水账!$B:$B,AT$3) -> 0 | AU9: =SUMIFS(出库流水账!$E:$E,出库流水账!$C:$C,$B9,出库流水账!$B:$B,AT$3) -> 1 | AV9: =SUMIFS(入库流水账!$E:$E,入库流水账!$C:$C,$B9,入库流水账!$B:$B,AV$3) -> 18 | AW9: =SUMIFS(出库流水账!$E:$E,出库流水账!$C:$C,$B9,出库流水账!$B:$B,AV$3) -> 1 | AX9: =SUMIFS(入库流水账!$E:$E,入库流水账!$C:$C,$B9,入库流水账!$B:$B,AX$3) -> 0 | AY9: =SUMIFS(出库流水账!$E:$E,出库流水账!$C:$C,$B9,出库流水账!$B:$B,AX$3) -> 0 | AZ9: =SUMIFS(入库流水账!$E:$E,入库流水账!$C:$C,$B9,入库流水账!$B:$B,AZ$3) -> 0 | BA9: =SUMIFS(出库流水账!$E:$E,出库流水账!$C:$C,$B9,出库流水账!$B:$B,AZ$3) -> 1 | BB9: =SUMIFS(入库流水账!$E:$E,入库流水账!$C:$C,$B9,入库流水账!$B:$B,BB$3) -> 0 | BC9: =SUMIFS(出库流水账!$E:$E,出库流水账!$C:$C,$B9,出库流水账!$B:$B,BB$3) -> 0 | BD9: =SUMIFS(入库流水账!$E:$E,入库流水账!$C:$C,$B9,入库流水账!$B:$B,BD$3) -> 0 | BE9: =SUMIFS(出库流水账!$E:$E,出库流水账!$C:$C,$B9,出库流水账!$B:$B,BD$3) -> 0 | BF9: =SUMIFS(入库流水账!$E:$E,入库流水账!$C:$C,$B9,入库流水账!$B:$B,BF$3) -> 0 | BG9: =SUMIFS(出库流水账!$E:$E,出库流水账!$C:$C,$B9,出库流水账!$B:$B,BF$3) -> 0 | BH9: =SUMIFS(入库流水账!$E:$E,入库流水账!$C:$C,$B9,入库流水账!$B:$B,BH$3) -> 0 | BI9: =SUMIFS(出库流水账!$E:$E,出库流水账!$C:$C,$B9,出库流水账!$B:$B,BH$3) -> 0 | BJ9: =SUMIFS(入库流水账!$E:$E,入库流水账!$C:$C,$B9,入库流水账!$B:$B,BJ$3) -> 0 | BK9: =SUMIFS(出库流水账!$E:$E,出库流水账!$C:$C,$B9,出库流水账!$B:$B,BJ$3) -> 1 | BL9: =SUMIFS(入库流水账!$E:$E,入库流水账!$C:$C,$B9,入库流水账!$B:$B,BL$3) -> 0 | BM9: =SUMIFS(出库流水账!$E:$E,出库流水账!$C:$C,$B9,出库流水账!$B:$B,BL$3) -> 1 | BN9: =SUMIFS(入库流水账!$E:$E,入库流水账!$C:$C,$B9,入库流水账!$B:$B,BN$3) -> 0 | BO9: =SUMIFS(出库流水账!$E:$E,出库流水账!$C:$C,$B9,出库流水账!$B:$B,BN$3) -> 1 | BP9: =SUMIFS(入库流水账!$E:$E,入库流水账!$C:$C,$B9,入库流水账!$B:$B,BP$3) -> 0 | BQ9: =SUMIFS(出库流水账!$E:$E,出库流水账!$C:$C,$B9,出库流水账!$B:$B,BP$3) -> 0
A10: =ROW()-4 -> 6 | B10: 海天鲜味生抽 | C10: =IFERROR(VLOOKUP(B10,产品数据!$B:$D,3,FALSE),"") -> 瓶 | D10: ='[2]米油调味品台账表 12月 '!G11 -> 10 | E10: =SUMIF($H$4:$BQ$4,$E$2,H10:BQ10) -> 6 | F10: =SUMIF($H$4:$BQ$4,$F$2,H10:BQ10) -> 11 | G10: =D10+E10-F10 -> 5 | H10: =SUMIFS(入库流水账!$E:$E,入库流水账!$C:$C,$B10,入库流水账!$B:$B,H$3) -> 0 | I10: =SUMIFS(出库流水账!$E:$E,出库流水账!$C:$C,$B10,出库流水账!$B:$B,H$3) -> 0 | J10: =SUMIFS(入库流水账!$E:$E,入库流水账!$C:$C,$B10,入库流水账!$B:$B,J$3) -> 0 | K10: =SUMIFS(出库流水账!$E:$E,出库流水账!$C:$C,$B10,出库流水账!$B:$B,J$3) -> 0 | L10: =SUMIFS(入库流水账!$E:$E,入库流水账!$C:$C,$B10,入库流水账!$B:$B,L$3) -> 0 | M10: =SUMIFS(出库流水账!$E:$E,出库流水账!$C:$C,$B10,出库流水账!$B:$B,L$3) -> 0 | N10: =SUMIFS(入库流水账!$E:$E,入库流水账!$C:$C,$B10,入库流水账!$B:$B,N$3) -> 0 | O10: =SUMIFS(出库流水账!$E:$E,出库流水账!$C:$C,$B10,出库流水账!$B:$B,N$3) -> 0 | P10: =SUMIFS(入库流水账!$E:$E,入库流水账!$C:$C,$B10,入库流水账!$B:$B,P$3) -> 0 | Q10: =SUMIFS(出库流水账!$E:$E,出库流水账!$C:$C,$B10,出库流水账!$B:$B,P$3) -> 0 | R10: =SUMIFS(入库流水账!$E:$E,入库流水账!$C:$C,$B10,入库流水账!$B:$B,R$3) -> 0 | S10: =SUMIFS(出库流水账!$E:$E,出库流水账!$C:$C,$B10,出库流水账!$B:$B,R$3) -> 1 | T10: =SUMIFS(入库流水账!$E:$E,入库流水账!$C:$C,$B10,入库流水账!$B:$B,T$3) -> 0 | U10: =SUMIFS(出库流水账!$E:$E,出库流水账!$C:$C,$B10,出库流水账!$B:$B,T$3) -> 1 | V10: =SUMIFS(入库流水账!$E:$E,入库流水账!$C:$C,$B10,入库流水账!$B:$B,V$3) -> 0 | W10: =SUMIFS(出库流水账!$E:$E,出库流水账!$C:$C,$B10,出库流水账!$B:$B,V$3) -> 0 | X10: =SUMIFS(入库流水账!$E:$E,入库流水账!$C:$C,$B10,入库流水账!$B:$B,X$3) -> 0 | Y10: =SUMIFS(出库流水账!$E:$E,出库流水账!$C:$C,$B10,出库流水账!$B:$B,X$3) -> 1 | Z10: =SUMIFS(入库流水账!$E:$E,入库流水账!$C:$C,$B10,入库流水账!$B:$B,Z$3) -> 0 | AA10: =SUMIFS(出库流水账!$E:$E,出库流水账!$C:$C,$B10,出库流水账!$B:$B,Z$3) -> 0 | AB10: =SUMIFS(入库流水账!$E:$E,入库流水账!$C:$C,$B10,入库流水账!$B:$B,AB$3) -> 0 | AC10: =SUMIFS(出库流水账!$E:$E,出库流水账!$C:$C,$B10,出库流水账!$B:$B,AB$3) -> 0 | AD10: =SUMIFS(入库流水账!$E:$E,入库流水账!$C:$C,$B10,入库流水账!$B:$B,AD$3) -> 0 | AE10: =SUMIFS(出库流水账!$E:$E,出库流水账!$C:$C,$B10,出库流水账!$B:$B,AD$3) -> 1 | AF10: =SUMIFS(入库流水账!$E:$E,入库流水账!$C:$C,$B10,入库流水账!$B:$B,AF$3) -> 0 | AG10: =SUMIFS(出库流水账!$E:$E,出库流水账!$C:$C,$B10,出库流水账!$B:$B,AF$3) -> 0 | AH10: =SUMIFS(入库流水账!$E:$E,入库流水账!$C:$C,$B10,入库流水账!$B:$B,AH$3) -> 0 | AI10: =SUMIFS(出库流水账!$E:$E,出库流水账!$C:$C,$B10,出库流水账!$B:$B,AH$3) -> 0 | AJ10: =SUMIFS(入库流水账!$E:$E,入库流水账!$C:$C,$B10,入库流水账!$B:$B,AJ$3) -> 0 | AK10: =SUMIFS(出库流水账!$E:$E,出库流水账!$C:$C,$B10,出库流水账!$B:$B,AJ$3) -> 1 | AL10: =SUMIFS(入库流水账!$E:$E,入库流水账!$C:$C,$B10,入库流水账!$B:$B,AL$3) -> 0 | AM10: =SUMIFS(出库流水账!$E:$E,出库流水账!$C:$C,$B10,出库流水账!$B:$B,AL$3) -> 0 | AN10: =SUMIFS(入库流水账!$E:$E,入库流水账!$C:$C,$B10,入库流水账!$B:$B,AN$3) -> 0 | AO10: =SUMIFS(出库流水账!$E:$E,出库流水账!$C:$C,$B10,出库流水账!$B:$B,AN$3) -> 0 | AP10: =SUMIFS(入库流水账!$E:$E,入库流水账!$C:$C,$B10,入库流水账!$B:$B,AP$3) -> 0 | AQ10: =SUMIFS(出库流水账!$E:$E,出库流水账!$C:$C,$B10,出库流水账!$B:$B,AP$3) -> 0 | AR10: =SUMIFS(入库流水账!$E:$E,入库流水账!$C:$C,$B10,入库流水账!$B:$B,AR$3) -> 0 | AS10: =SUMIFS(出库流水账!$E:$E,出库流水账!$C:$C,$B10,出库流水账!$B:$B,AR$3) -> 1 | AT10: =SUMIFS(入库流水账!$E:$E,入库流水账!$C:$C,$B10,入库流水账!$B:$B,AT$3) -> 6 | AU10: =SUMIFS(出库流水账!$E:$E,出库流水账!$C:$C,$B10,出库流水账!$B:$B,AT$3) -> 0 | AV10: =SUMIFS(入库流水账!$E:$E,入库流水账!$C:$C,$B10,入库流水账!$B:$B,AV$3) -> 0 | AW10: =SUMIFS(出库流水账!$E:$E,出库流水账!$C:$C,$B10,出库流水账!$B:$B,AV$3) -> 1 | AX10: =SUMIFS(入库流水账!$E:$E,入库流水账!$C:$C,$B10,入库流水账!$B:$B,AX$3) -> 0 | AY10: =SUMIFS(出库流水账!$E:$E,出库流水账!$C:$C,$B10,出库流水账!$B:$B,AX$3) -> 0 | AZ10: =SUMIFS(入库流水账!$E:$E,入库流水账!$C:$C,$B10,入库流水账!$B:$B,AZ$3) -> 0 | BA10: =SUMIFS(出库流水账!$E:$E,出库流水账!$C:$C,$B10,出库流水账!$B:$B,AZ$3) -> 1 | BB10: =SUMIFS(入库流水账!$E:$E,入库流水账!$C:$C,$B10,入库流水账!$B:$B,BB$3) -> 0 | BC10: =SUMIFS(出库流水账!$E:$E,出库流水账!$C:$C,$B10,出库流水账!$B:$B,BB$3) -> 0 | BD10: =SUMIFS(入库流水账!$E:$E,入库流水账!$C:$C,$B10,入库流水账!$B:$B,BD$3) -> 0 | BE10: =SUMIFS(出库流水账!$E:$E,出库流水账!$C:$C,$B10,出库流水账!$B:$B,BD$3) -> 0 | BF10: =SUMIFS(入库流水账!$E:$E,入库流水账!$C:$C,$B10,入库流水账!$B:$B,BF$3) -> 0 | BG10: =SUMIFS(出库流水账!$E:$E,出库流水账!$C:$C,$B10,出库流水账!$B:$B,BF$3) -> 1 | BH10: =SUMIFS(入库流水账!$E:$E,入库流水账!$C:$C,$B10,入库流水账!$B:$B,BH$3) -> 0 | BI10: =SUMIFS(出库流水账!$E:$E,出库流水账!$C:$C,$B10,出库流水账!$B:$B,BH$3) -> 0 | BJ10: =SUMIFS(入库流水账!$E:$E,入库流水账!$C:$C,$B10,入库流水账!$B:$B,BJ$3) -> 0 | BK10: =SUMIFS(出库流水账!$E:$E,出库流水账!$C:$C,$B10,出库流水账!$B:$B,BJ$3) -> 1 | BL10: =SUMIFS(入库流水账!$E:$E,入库流水账!$C:$C,$B10,入库流水账!$B:$B,BL$3) -> 0 | BM10: =SUMIFS(出库流水账!$E:$E,出库流水账!$C:$C,$B10,出库流水账!$B:$B,BL$3) -> 1 | BN10: =SUMIFS(入库流水账!$E:$E,入库流水账!$C:$C,$B10,入库流水账!$B:$B,BN$3) -> 0 | BO10: =SUMIFS(出库流水账!$E:$E,出库流水账!$C:$C,$B10,出库流水账!$B:$B,BN$3) -> 0 | BP10: =SUMIFS(入库流水账!$E:$E,入库流水账!$C:$C,$B10,入库流水账!$B:$B,BP$3) -> 0 | BQ10: =SUMIFS(出库流水账!$E:$E,出库流水账!$C:$C,$B10,出库流水账!$B:$B,BP$3) -> 0
A11: =ROW()-4 -> 7 | B11: 李锦记蒸鱼豉油 | C11: =IFERROR(VLOOKUP(B11,产品数据!$B:$D,3,FALSE),"") -> 瓶 | D11: 3 | E11: =SUMIF($H$4:$BQ$4,$E$2,H11:BQ11) -> 6 | F11: =SUMIF($H$4:$BQ$4,$F$2,H11:BQ11) -> 4 | G11: =D11+E11-F11 -> 5 | H11: =SUMIFS(入库流水账!$E:$E,入库流水账!$C:$C,$B11,入库流水账!$B:$B,H$3) -> 0 | I11: =SUMIFS(出库流水账!$E:$E,出库流水账!$C:$C,$B11,出库流水账!$B:$B,H$3) -> 0 | J11: =SUMIFS(入库流水账!$E:$E,入库流水账!$C:$C,$B11,入库流水账!$B:$B,J$3) -> 0 | K11: =SUMIFS(出库流水账!$E:$E,出库流水账!$C:$C,$B11,出库流水账!$B:$B,J$3) -> 0 | L11: =SUMIFS(入库流水账!$E:$E,入库流水账!$C:$C,$B11,入库流水账!$B:$B,L$3) -> 0 | M11: =SUMIFS(出库流水账!$E:$E,出库流水账!$C:$C,$B11,出库流水账!$B:$B,L$3) -> 0 | N11: =SUMIFS(入库流水账!$E:$E,入库流水账!$C:$C,$B11,入库流水账!$B:$B,N$3) -> 0 | O11: =SUMIFS(出库流水账!$E:$E,出库流水账!$C:$C,$B11,出库流水账!$B:$B,N$3) -> 0 | P11: =SUMIFS(入库流水账!$E:$E,入库流水账!$C:$C,$B11,入库流水账!$B:$B,P$3) -> 0 | Q11: =SUMIFS(出库流水账!$E:$E,出库流水账!$C:$C,$B11,出库流水账!$B:$B,P$3) -> 0 | R11: =SUMIFS(入库流水账!$E:$E,入库流水账!$C:$C,$B11,入库流水账!$B:$B,R$3) -> 0 | S11: =SUMIFS(出库流水账!$E:$E,出库流水账!$C:$C,$B11,出库流水账!$B:$B,R$3) -> 1 | T11: =SUMIFS(入库流水账!$E:$E,入库流水账!$C:$C,$B11,入库流水账!$B:$B,T$3) -> 6 | U11: =SUMIFS(出库流水账!$E:$E,出库流水账!$C:$C,$B11,出库流水账!$B:$B,T$3) -> 0 | V11: =SUMIFS(入库流水账!$E:$E,入库流水账!$C:$C,$B11,入库流水账!$B:$B,V$3) -> 0 | W11: =SUMIFS(出库流水账!$E:$E,出库流水账!$C:$C,$B11,出库流水账!$B:$B,V$3) -> 0 | X11: =SUMIFS(入库流水账!$E:$E,入库流水账!$C:$C,$B11,入库流水账!$B:$B,X$3) -> 0 | Y11: =SUMIFS(出库流水账!$E:$E,出库流水账!$C:$C,$B11,出库流水账!$B:$B,X$3) -> 0 | Z11: =SUMIFS(入库流水账!$E:$E,入库流水账!$C:$C,$B11,入库流水账!$B:$B,Z$3) -> 0 | AA11: =SUMIFS(出库流水账!$E:$E,出库流水账!$C:$C,$B11,出库流水账!$B:$B,Z$3) -> 0 | AB11: =SUMIFS(入库流水账!$E:$E,入库流水账!$C:$C,$B11,入库流水账!$B:$B,AB$3) -> 0 | AC11: =SUMIFS(出库流水账!$E:$E,出库流水账!$C:$C,$B11,出库流水账!$B:$B,AB$3) -> 0 | AD11: =SUMIFS(入库流水账!$E:$E,入库流水账!$C:$C,$B11,入库流水账!$B:$B,AD$3) -> 0 | AE11: =SUMIFS(出库流水账!$E:$E,出库流水账!$C:$C,$B11,出库流水账!$B:$B,AD$3) -> 0 | AF11: =SUMIFS(入库流水账!$E:$E,入库流水账!$C:$C,$B11,入库流水账!$B:$B,AF$3) -> 0 | AG11: =SUMIFS(出库流水账!$E:$E,出库流水账!$C:$C,$B11,出库流水账!$B:$B,AF$3) -> 1 | AH11: =SUMIFS(入库流水账!$E:$E,入库流水账!$C:$C,$B11,入库流水账!$B:$B,AH$3) -> 0 | AI11: =SUMIFS(出库流水账!$E:$E,出库流水账!$C:$C,$B11,出库流水账!$B:$B,AH$3) -> 1 | AJ11: =SUMIFS(入库流水账!$E:$E,入库流水账!$C:$C,$B11,入库流水账!$B:$B,AJ$3) -> 0 | AK11: =SUMIFS(出库流水账!$E:$E,出库流水账!$C:$C,$B11,出库流水账!$B:$B,AJ$3) -> 0 | AL11: =SUMIFS(入库流水账!$E:$E,入库流水账!$C:$C,$B11,入库流水账!$B:$B,AL$3) -> 0 | AM11: =SUMIFS(出库流水账!$E:$E,出库流水账!$C:$C,$B11,出库流水账!$B:$B,AL$3) -> 0 | AN11: =SUMIFS(入库流水账!$E:$E,入库流水账!$C:$C,$B11,入库流水账!$B:$B,AN$3) -> 0 | AO11: =SUMIFS(出库流水账!$E:$E,出库流水账!$C:$C,$B11,出库流水账!$B:$B,AN$3) -> 0 | AP11: =SUMIFS(入库流水账!$E:$E,入库流水账!$C:$C,$B11,入库流水账!$B:$B,AP$3) -> 0 | AQ11: =SUMIFS(出库流水账!$E:$E,出库流水账!$C:$C,$B11,出库流水账!$B:$B,AP$3) -> 0 | AR11: =SUMIFS(入库流水账!$E:$E,入库流水账!$C:$C,$B11,入库流水账!$B:$B,AR$3) -> 0 | AS11: =SUMIFS(出库流水账!$E:$E,出库流水账!$C:$C,$B11,出库流水账!$B:$B,AR$3) -> 0 | AT11: =SUMIFS(入库流水账!$E:$E,入库流水账!$C:$C,$B11,入库流水账!$B:$B,AT$3) -> 0 | AU11: =SUMIFS(出库流水账!$E:$E,出库流水账!$C:$C,$B11,出库流水账!$B:$B,AT$3) -> 0 | AV11: =SUMIFS(入库流水账!$E:$E,入库流水账!$C:$C,$B11,入库流水账!$B:$B,AV$3) -> 0 | AW11: =SUMIFS(出库流水账!$E:$E,出库流水账!$C:$C,$B11,出库流水账!$B:$B,AV$3) -> 0 | AX11: =SUMIFS(入库流水账!$E:$E,入库流水账!$C:$C,$B11,入库流水账!$B:$B,AX$3) -> 0 | AY11: =SUMIFS(出库流水账!$E:$E,出库流水账!$C:$C,$B11,出库流水账!$B:$B,AX$3) -> 0 | AZ11: =SUMIFS(入库流水账!$E:$E,入库流水账!$C:$C,$B11,入库流水账!$B:$B,AZ$3) -> 0 | BA11: =SUMIFS(出库流水账!$E:$E,出库流水账!$C:$C,$B11,出库流水账!$B:$B,AZ$3) -> 0 | BB11: =SUMIFS(入库流水账!$E:$E,入库流水账!$C:$C,$B11,入库流水账!$B:$B,BB$3) -> 0 | BC11: =SUMIFS(出库流水账!$E:$E,出库流水账!$C:$C,$B11,出库流水账!$B:$B,BB$3) -> 0 | BD11: =SUMIFS(入库流水账!$E:$E,入库流水账!$C:$C,$B11,入库流水账!$B:$B,BD$3) -> 0 | BE11: =SUMIFS(出库流水账!$E:$E,出库流水账!$C:$C,$B11,出库流水账!$B:$B,BD$3) -> 0 | BF11: =SUMIFS(入库流水账!$E:$E,入库流水账!$C:$C,$B11,入库流水账!$B:$B,BF$3) -> 0 | BG11: =SUMIFS(出库流水账!$E:$E,出库流水账!$C:$C,$B11,出库流水账!$B:$B,BF$3) -> 0 | BH11: =SUMIFS(入库流水账!$E:$E,入库流水账!$C:$C,$B11,入库流水账!$B:$B,BH$3) -> 0 | BI11: =SUMIFS(出库流水账!$E:$E,出库流水账!$C:$C,$B11,出库流水账!$B:$B,BH$3) -> 0 | BJ11: =SUMIFS(入库流水账!$E:$E,入库流水账!$C:$C,$B11,入库流水账!$B:$B,BJ$3) -> 0 | BK11: =SUMIFS(出库流水账!$E:$E,出库流水账!$C:$C,$B11,出库流水账!$B:$B,BJ$3) -> 0 | BL11: =SUMIFS(入库流水账!$E:$E,入库流水账!$C:$C,$B11,入库流水账!$B:$B,BL$3) -> 0 | BM11: =SUMIFS(出库流水账!$E:$E,出库流水账!$C:$C,$B11,出库流水账!$B:$B,BL$3) -> 0 | BN11: =SUMIFS(入库流水账!$E:$E,入库流水账!$C:$C,$B11,入库流水账!$B:$B,BN$3) -> 0 | BO11: =SUMIFS(出库流水账!$E:$E,出库流水账!$C:$C,$B11,出库流水账!$B:$B,BN$3) -> 1 | BP11: =SUMIFS(入库流水账!$E:$E,入库流水账!$C:$C,$B11,入库流水账!$B:$B,BP$3) -> 0 | BQ11: =SUMIFS(出库流水账!$E:$E,出库流水账!$C:$C,$B11,出库流水账!$B:$B,BP$3) -> 0
A12: =ROW()-4 -> 8 | B12: 李锦记番茄沙司 | C12: =IFERROR(VLOOKUP(B12,产品数据!$B:$D,3,FALSE),"") -> 瓶 | D12: 10 | E12: =SUMIF($H$4:$BQ$4,$E$2,H12:BQ12) -> 0 | F12: =SUMIF($H$4:$BQ$4,$F$2,H12:BQ12) -> 0 | G12: =D12+E12-F12 -> 10 | H12: =SUMIFS(入库流水账!$E:$E,入库流水账!$C:$C,$B12,入库流水账!$B:$B,H$3) -> 0 | I12: =SUMIFS(出库流水账!$E:$E,出库流水账!$C:$C,$B12,出库流水账!$B:$B,H$3) -> 0 | J12: =SUMIFS(入库流水账!$E:$E,入库流水账!$C:$C,$B12,入库流水账!$B:$B,J$3) -> 0 | K12: =SUMIFS(出库流水账!$E:$E,出库流水账!$C:$C,$B12,出库流水账!$B:$B,J$3) -> 0 | L12: =SUMIFS(入库流水账!$E:$E,入库流水账!$C:$C,$B12,入库流水账!$B:$B,L$3) -> 0 | M12: =SUMIFS(出库流水账!$E:$E,出库流水账!$C:$C,$B12,出库流水账!$B:$B,L$3) -> 0 | N12: =SUMIFS(入库流水账!$E:$E,入库流水账!$C:$C,$B12,入库流水账!$B:$B,N$3) -> 0 | O12: =SUMIFS(出库流水账!$E:$E,出库流水账!$C:$C,$B12,出库流水账!$B:$B,N$3) -> 0 | P12: =SUMIFS(入库流水账!$E:$E,入库流水账!$C:$C,$B12,入库流水账!$B:$B,P$3) -> 0 | Q12: =SUMIFS(出库流水账!$E:$E,出库流水账!$C:$C,$B12,出库流水账!$B:$B,P$3) -> 0 | R12: =SUMIFS(入库流水账!$E:$E,入库流水账!$C:$C,$B12,入库流水账!$B:$B,R$3) -> 0 | S12: =SUMIFS(出库流水账!$E:$E,出库流水账!$C:$C,$B12,出库流水账!$B:$B,R$3) -> 0 | T12: =SUMIFS(入库流水账!$E:$E,入库流水账!$C:$C,$B12,入库流水账!$B:$B,T$3) -> 0 | U12: =SUMIFS(出库流水账!$E:$E,出库流水账!$C:$C,$B12,出库流水账!$B:$B,T$3) -> 0 | V12: =SUMIFS(入库流水账!$E:$E,入库流水账!$C:$C,$B12,入库流水账!$B:$B,V$3) -> 0 | W12: =SUMIFS(出库流水账!$E:$E,出库流水账!$C:$C,$B12,出库流水账!$B:$B,V$3) -> 0 | X12: =SUMIFS(入库流水账!$E:$E,入库流水账!$C:$C,$B12,入库流水账!$B:$B,X$3) -> 0 | Y12: =SUMIFS(出库流水账!$E:$E,出库流水账!$C:$C,$B12,出库流水账!$B:$B,X$3) -> 0 | Z12: =SUMIFS(入库流水账!$E:$E,入库流水账!$C:$C,$B12,入库流水账!$B:$B,Z$3) -> 0 | AA12: =SUMIFS(出库流水账!$E:$E,出库流水账!$C:$C,$B12,出库流水账!$B:$B,Z$3) -> 0 | AB12: =SUMIFS(入库流水账!$E:$E,入库流水账!$C:$C,$B12,入库流水账!$B:$B,AB$3) -> 0 | AC12: =SUMIFS(出库流水账!$E:$E,出库流水账!$C:$C,$B12,出库流水账!$B:$B,AB$3) -> 0 | AD12: =SUMIFS(入库流水账!$E:$E,入库流水账!$C:$C,$B12,入库流水账!$B:$B,AD$3) -> 0 | AE12: =SUMIFS(出库流水账!$E:$E,出库流水账!$C:$C,$B12,出库流水账!$B:$B,AD$3) -> 0 | AF12: =SUMIFS(入库流水账!$E:$E,入库流水账!$C:$C,$B12,入库流水账!$B:$B,AF$3) -> 0 | AG12: =SUMIFS(出库流水账!$E:$E,出库流水账!$C:$C,$B12,出库流水账!$B:$B,AF$3) -> 0 | AH12: =SUMIFS(入库流水账!$E:$E,入库流水账!$C:$C,$B12,入库流水账!$B:$B,AH$3) -> 0 | AI12: =SUMIFS(出库流水账!$E:$E,出库流水账!$C:$C,$B12,出库流水账!$B:$B,AH$3) -> 0 | AJ12: =SUMIFS(入库流水账!$E:$E,入库流水账!$C:$C,$B12,入库流水账!$B:$B,AJ$3) -> 0 | AK12: =SUMIFS(出库流水账!$E:$E,出库流水账!$C:$C,$B12,出库流水账!$B:$B,AJ$3) -> 0 | AL12: =SUMIFS(入库流水账!$E:$E,入库流水账!$C:$C,$B12,入库流水账!$B:$B,AL$3) -> 0 | AM12: =SUMIFS(出库流水账!$E:$E,出库流水账!$C:$C,$B12,出库流水账!$B:$B,AL$3) -> 0 | AN12: =SUMIFS(入库流水账!$E:$E,入库流水账!$C:$C,$B12,入库流水账!$B:$B,AN$3) -> 0 | AO12: =SUMIFS(出库流水账!$E:$E,出库流水账!$C:$C,$B12,出库流水账!$B:$B,AN$3) -> 0 | AP12: =SUMIFS(入库流水账!$E:$E,入库流水账!$C:$C,$B12,入库流水账!$B:$B,AP$3) -> 0 | AQ12: =SUMIFS(出库流水账!$E:$E,出库流水账!$C:$C,$B12,出库流水账!$B:$B,AP$3) -> 0 | AR12: =SUMIFS(入库流水账!$E:$E,入库流水账!$C:$C,$B12,入库流水账!$B:$B,AR$3) -> 0 | AS12: =SUMIFS(出库流水账!$E:$E,出库流水账!$C:$C,$B12,出库流水账!$B:$B,AR$3) -> 0 | AT12: =SUMIFS(入库流水账!$E:$E,入库流水账!$C:$C,$B12,入库流水账!$B:$B,AT$3) -> 0 | AU12: =SUMIFS(出库流水账!$E:$E,出库流水账!$C:$C,$B12,出库流水账!$B:$B,AT$3) -> 0 | AV12: =SUMIFS(入库流水账!$E:$E,入库流水账!$C:$C,$B12,入库流水账!$B:$B,AV$3) -> 0 | AW12: =SUMIFS(出库流水账!$E:$E,出库流水账!$C:$C,$B12,出库流水账!$B:$B,AV$3) -> 0 | AX12: =SUMIFS(入库流水账!$E:$E,入库流水账!$C:$C,$B12,入库流水账!$B:$B,AX$3) -> 0 | AY12: =SUMIFS(出库流水账!$E:$E,出库流水账!$C:$C,$B12,出库流水账!$B:$B,AX$3) -> 0 | AZ12: =SUMIFS(入库流水账!$E:$E,入库流水账!$C:$C,$B12,入库流水账!$B:$B,AZ$3) -> 0 | BA12: =SUMIFS(出库流水账!$E:$E,出库流水账!$C:$C,$B12,出库流水账!$B:$B,AZ$3) -> 0 | BB12: =SUMIFS(入库流水账!$E:$E,入库流水账!$C:$C,$B12,入库流水账!$B:$B,BB$3) -> 0 | BC12: =SUMIFS(出库流水账!$E:$E,出库流水账!$C:$C,$B12,出库流水账!$B:$B,BB$3) -> 0 | BD12: =SUMIFS(入库流水账!$E:$E,入库流水账!$C:$C,$B12,入库流水账!$B:$B,BD$3) -> 0 | BE12: =SUMIFS(出库流水账!$E:$E,出库流水账!$C:$C,$B12,出库流水账!$B:$B,BD$3) -> 0 | BF12: =SUMIFS(入库流水账!$E:$E,入库流水账!$C:$C,$B12,入库流水账!$B:$B,BF$3) -> 0 | BG12: =SUMIFS(出库流水账!$E:$E,出库流水账!$C:$C,$B12,出库流水账!$B:$B,BF$3) -> 0 | BH12: =SUMIFS(入库流水账!$E:$E,入库流水账!$C:$C,$B12,入库流水账!$B:$B,BH$3) -> 0 | BI12: =SUMIFS(出库流水账!$E:$E,出库流水账!$C:$C,$B12,出库流水账!$B:$B,BH$3) -> 0 | BJ12: =SUMIFS(入库流水账!$E:$E,入库流水账!$C:$C,$B12,入库流水账!$B:$B,BJ$3) -> 0 | BK12: =SUMIFS(出库流水账!$E:$E,出库流水账!$C:$C,$B12,出库流水账!$B:$B,BJ$3) -> 0 | BL12: =SUMIFS(入库流水账!$E:$E,入库流水账!$C:$C,$B12,入库流水账!$B:$B,BL$3) -> 0 | BM12: =SUMIFS(出库流水账!$E:$E,出库流水账!$C:$C,$B12,出库流水账!$B:$B,BL$3) -> 0 | BN12: =SUMIFS(入库流水账!$E:$E,入库流水账!$C:$C,$B12,入库流水账!$B:$B,BN$3) -> 0 | BO12: =SUMIFS(出库流水账!$E:$E,出库流水账!$C:$C,$B12,出库流水账!$B:$B,BN$3) -> 0 | BP12: =SUMIFS(入库流水账!$E:$E,入库流水账!$C:$C,$B12,入库流水账!$B:$B,BP$3) -> 0 | BQ12: =SUMIFS(出库流水账!$E:$E,出库流水账!$C:$C,$B12,出库流水账!$B:$B,BP$3) -> 0
A13: =ROW()-4 -> 9 | B13: 恒顺陈醋 | C13: =IFERROR(VLOOKUP(B13,产品数据!$B:$D,3,FALSE),"") -> 瓶 | D13: 7 | E13: =SUMIF($H$4:$BQ$4,$E$2,H13:BQ13) -> 12 | F13: =SUMIF($H$4:$BQ$4,$F$2,H13:BQ13) -> 5 | G13: =D13+E13-F13 -> 14 | H13: =SUMIFS(入库流水账!$E:$E,入库流水账!$C:$C,$B13,入库流水账!$B:$B,H$3) -> 0 | I13: =SUMIFS(出库流水账!$E:$E,出库流水账!$C:$C,$B13,出库流水账!$B:$B,H$3) -> 0 | J13: =SUMIFS(入库流水账!$E:$E,入库流水账!$C:$C,$B13,入库流水账!$B:$B,J$3) -> 0 | K13: =SUMIFS(出库流水账!$E:$E,出库流水账!$C:$C,$B13,出库流水账!$B:$B,J$3) -> 0 | L13: =SUMIFS(入库流水账!$E:$E,入库流水账!$C:$C,$B13,入库流水账!$B:$B,L$3) -> 0 | M13: =SUMIFS(出库流水账!$E:$E,出库流水账!$C:$C,$B13,出库流水账!$B:$B,L$3) -> 0 | N13: =SUMIFS(入库流水账!$E:$E,入库流水账!$C:$C,$B13,入库流水账!$B:$B,N$3) -> 0 | O13: =SUMIFS(出库流水账!$E:$E,出库流水账!$C:$C,$B13,出库流水账!$B:$B,N$3) -> 0 | P13: =SUMIFS(入库流水账!$E:$E,入库流水账!$C:$C,$B13,入库流水账!$B:$B,P$3) -> 0 | Q13: =SUMIFS(出库流水账!$E:$E,出库流水账!$C:$C,$B13,出库流水账!$B:$B,P$3) -> 1 | R13: =SUMIFS(入库流水账!$E:$E,入库流水账!$C:$C,$B13,入库流水账!$B:$B,R$3) -> 0 | S13: =SUMIFS(出库流水账!$E:$E,出库流水账!$C:$C,$B13,出库流水账!$B:$B,R$3) -> 0 | T13: =SUMIFS(入库流水账!$E:$E,入库流水账!$C:$C,$B13,入库流水账!$B:$B,T$3) -> 0 | U13: =SUMIFS(出库流水账!$E:$E,出库流水账!$C:$C,$B13,出库流水账!$B:$B,T$3) -> 0 | V13: =SUMIFS(入库流水账!$E:$E,入库流水账!$C:$C,$B13,入库流水账!$B:$B,V$3) -> 0 | W13: =SUMIFS(出库流水账!$E:$E,出库流水账!$C:$C,$B13,出库流水账!$B:$B,V$3) -> 0 | X13: =SUMIFS(入库流水账!$E:$E,入库流水账!$C:$C,$B13,入库流水账!$B:$B,X$3) -> 0 | Y13: =SUMIFS(出库流水账!$E:$E,出库流水账!$C:$C,$B13,出库流水账!$B:$B,X$3) -> 0 | Z13: =SUMIFS(入库流水账!$E:$E,入库流水账!$C:$C,$B13,入库流水账!$B:$B,Z$3) -> 0 | AA13: =SUMIFS(出库流水账!$E:$E,出库流水账!$C:$C,$B13,出库流水账!$B:$B,Z$3) -> 0 | AB13: =SUMIFS(入库流水账!$E:$E,入库流水账!$C:$C,$B13,入库流水账!$B:$B,AB$3) -> 0 | AC13: =SUMIFS(出库流水账!$E:$E,出库流水账!$C:$C,$B13,出库流水账!$B:$B,AB$3) -> 0 | AD13: =SUMIFS(入库流水账!$E:$E,入库流水账!$C:$C,$B13,入库流水账!$B:$B,AD$3) -> 0 | AE13: =SUMIFS(出库流水账!$E:$E,出库流水账!$C:$C,$B13,出库流水账!$B:$B,AD$3) -> 2 | AF13: =SUMIFS(入库流水账!$E:$E,入库流水账!$C:$C,$B13,入库流水账!$B:$B,AF$3) -> 0 | AG13: =SUMIFS(出库流水账!$E:$E,出库流水账!$C:$C,$B13,出库流水账!$B:$B,AF$3) -> 0 | AH13: =SUMIFS(入库流水账!$E:$E,入库流水账!$C:$C,$B13,入库流水账!$B:$B,AH$3) -> 0 | AI13: =SUMIFS(出库流水账!$E:$E,出库流水账!$C:$C,$B13,出库流水账!$B:$B,AH$3) -> 2 | AJ13: =SUMIFS(入库流水账!$E:$E,入库流水账!$C:$C,$B13,入库流水账!$B:$B,AJ$3) -> 12 | AK13: =SUMIFS(出库流水账!$E:$E,出库流水账!$C:$C,$B13,出库流水账!$B:$B,AJ$3) -> 0 | AL13: =SUMIFS(入库流水账!$E:$E,入库流水账!$C:$C,$B13,入库流水账!$B:$B,AL$3) -> 0 | AM13: =SUMIFS(出库流水账!$E:$E,出库流水账!$C:$C,$B13,出库流水账!$B:$B,AL$3) -> 0 | AN13: =SUMIFS(入库流水账!$E:$E,入库流水账!$C:$C,$B13,入库流水账!$B:$B,AN$3) -> 0 | AO13: =SUMIFS(出库流水账!$E:$E,出库流水账!$C:$C,$B13,出库流水账!$B:$B,AN$3) -> 0 | AP13: =SUMIFS(入库流水账!$E:$E,入库流水账!$C:$C,$B13,入库流水账!$B:$B,AP$3) -> 0 | AQ13: =SUMIFS(出库流水账!$E:$E,出库流水账!$C:$C,$B13,出库流水账!$B:$B,AP$3) -> 0 | AR13: =SUMIFS(入库流水账!$E:$E,入库流水账!$C:$C,$B13,入库流水账!$B:$B,AR$3) -> 0 | AS13: =SUMIFS(出库流水账!$E:$E,出库流水账!$C:$C,$B13,出库流水账!$B:$B,AR$3) -> 0 | AT13: =SUMIFS(入库流水账!$E:$E,入库流水账!$C:$C,$B13,入库流水账!$B:$B,AT$3) -> 0 | AU13: =SUMIFS(出库流水账!$E:$E,出库流水账!$C:$C,$B13,出库流水账!$B:$B,AT$3) -> 0 | AV13: =SUMIFS(入库流水账!$E:$E,入库流水账!$C:$C,$B13,入库流水账!$B:$B,AV$3) -> 0 | AW13: =SUMIFS(出库流水账!$E:$E,出库流水账!$C:$C,$B13,出库流水账!$B:$B,AV$3) -> 0 | AX13: =SUMIFS(入库流水账!$E:$E,入库流水账!$C:$C,$B13,入库流水账!$B:$B,AX$3) -> 0 | AY13: =SUMIFS(出库流水账!$E:$E,出库流水账!$C:$C,$B13,出库流水账!$B:$B,AX$3) -> 0 | AZ13: =SUMIFS(入库流水账!$E:$E,入库流水账!$C:$C,$B13,入库流水账!$B:$B,AZ$3) -> 0 | BA13: =SUMIFS(出库流水账!$E:$E,出库流水账!$C:$C,$B13,出库流水账!$B:$B,AZ$3) -> 0 | BB13: =SUMIFS(入库流水账!$E:$E,入库流水账!$C:$C,$B13,入库流水账!$B:$B,BB$3) -> 0 | BC13: =SUMIFS(出库流水账!$E:$E,出库流水账!$C:$C,$B13,出库流水账!$B:$B,BB$3) -> 0 | BD13: =SUMIFS(入库流水账!$E:$E,入库流水账!$C:$C,$B13,入库流水账!$B:$B,BD$3) -> 0 | BE13: =SUMIFS(出库流水账!$E:$E,出库流水账!$C:$C,$B13,出库流水账!$B:$B,BD$3) -> 0 | BF13: =SUMIFS(入库流水账!$E:$E,入库流水账!$C:$C,$B13,入库流水账!$B:$B,BF$3) -> 0 | BG13: =SUMIFS(出库流水账!$E:$E,出库流水账!$C:$C,$B13,出库流水账!$B:$B,BF$3) -> 0 | BH13: =SUMIFS(入库流水账!$E:$E,入库流水账!$C:$C,$B13,入库流水账!$B:$B,BH$3) -> 0 | BI13: =SUMIFS(出库流水账!$E:$E,出库流水账!$C:$C,$B13,出库流水账!$B:$B,BH$3) -> 0 | BJ13: =SUMIFS(入库流水账!$E:$E,入库流水账!$C:$C,$B13,入库流水账!$B:$B,BJ$3) -> 0 | BK13: =SUMIFS(出库流水账!$E:$E,出库流水账!$C:$C,$B13,出库流水账!$B:$B,BJ$3) -> 0 | BL13: =SUMIFS(入库流水账!$E:$E,入库流水账!$C:$C,$B13,入库流水账!$B:$B,BL$3) -> 0 | BM13: =SUMIFS(出库流水账!$E:$E,出库流水账!$C:$C,$B13,出库流水账!$B:$B,BL$3) -> 0 | BN13: =SUMIFS(入库流水账!$E:$E,入库流水账!$C:$C,$B13,入库流水账!$B:$B,BN$3) -> 0 | BO13: =SUMIFS(出库流水账!$E:$E,出库流水账!$C:$C,$B13,出库流水账!$B:$B,BN$3) -> 0 | BP13: =SUMIFS(入库流水账!$E:$E,入库流水账!$C:$C,$B13,入库流水账!$B:$B,BP$3) -> 0 | BQ13: =SUMIFS(出库流水账!$E:$E,出库流水账!$C:$C,$B13,出库流水账!$B:$B,BP$3) -> 0
A14: =ROW()-4 -> 10 | B14: 恒顺白醋 | C14: =IFERROR(VLOOKUP(B14,产品数据!$B:$D,3,FALSE),"") -> 瓶 | D14: 4 | E14: =SUMIF($H$4:$BQ$4,$E$2,H14:BQ14) -> 36 | F14: =SUMIF($H$4:$BQ$4,$F$2,H14:BQ14) -> 7 | G14: =D14+E14-F14 -> 33 | H14: =SUMIFS(入库流水账!$E:$E,入库流水账!$C:$C,$B14,入库流水账!$B:$B,H$3) -> 0 | I14: =SUMIFS(出库流水账!$E:$E,出库流水账!$C:$C,$B14,出库流水账!$B:$B,H$3) -> 0 | J14: =SUMIFS(入库流水账!$E:$E,入库流水账!$C:$C,$B14,入库流水账!$B:$B,J$3) -> 0 | K14: =SUMIFS(出库流水账!$E:$E,出库流水账!$C:$C,$B14,出库流水账!$B:$B,J$3) -> 0 | L14: =SUMIFS(入库流水账!$E:$E,入库流水账!$C:$C,$B14,入库流水账!$B:$B,L$3) -> 0 | M14: =SUMIFS(出库流水账!$E:$E,出库流水账!$C:$C,$B14,出库流水账!$B:$B,L$3) -> 0 | N14: =SUMIFS(入库流水账!$E:$E,入库流水账!$C:$C,$B14,入库流水账!$B:$B,N$3) -> 0 | O14: =SUMIFS(出库流水账!$E:$E,出库流水账!$C:$C,$B14,出库流水账!$B:$B,N$3) -> 2 | P14: =SUMIFS(入库流水账!$E:$E,入库流水账!$C:$C,$B14,入库流水账!$B:$B,P$3) -> 0 | Q14: =SUMIFS(出库流水账!$E:$E,出库流水账!$C:$C,$B14,出库流水账!$B:$B,P$3) -> 1 | R14: =SUMIFS(入库流水账!$E:$E,入库流水账!$C:$C,$B14,入库流水账!$B:$B,R$3) -> 0 | S14: =SUMIFS(出库流水账!$E:$E,出库流水账!$C:$C,$B14,出库流水账!$B:$B,R$3) -> 0 | T14: =SUMIFS(入库流水账!$E:$E,入库流水账!$C:$C,$B14,入库流水账!$B:$B,T$3) -> 12 | U14: =SUMIFS(出库流水账!$E:$E,出库流水账!$C:$C,$B14,出库流水账!$B:$B,T$3) -> 0 | V14: =SUMIFS(入库流水账!$E:$E,入库流水账!$C:$C,$B14,入库流水账!$B:$B,V$3) -> 0 | W14: =SUMIFS(出库流水账!$E:$E,出库流水账!$C:$C,$B14,出库流水账!$B:$B,V$3) -> 0 | X14: =SUMIFS(入库流水账!$E:$E,入库流水账!$C:$C,$B14,入库流水账!$B:$B,X$3) -> 0 | Y14: =SUMIFS(出库流水账!$E:$E,出库流水账!$C:$C,$B14,出库流水账!$B:$B,X$3) -> 0 | Z14: =SUMIFS(入库流水账!$E:$E,入库流水账!$C:$C,$B14,入库流水账!$B:$B,Z$3) -> 0 | AA14: =SUMIFS(出库流水账!$E:$E,出库流水账!$C:$C,$B14,出库流水账!$B:$B,Z$3) -> 0 | AB14: =SUMIFS(入库流水账!$E:$E,入库流水账!$C:$C,$B14,入库流水账!$B:$B,AB$3) -> 0 | AC14: =SUMIFS(出库流水账!$E:$E,出库流水账!$C:$C,$B14,出库流水账!$B:$B,AB$3) -> 0 | AD14: =SUMIFS(入库流水账!$E:$E,入库流水账!$C:$C,$B14,入库流水账!$B:$B,AD$3) -> 0 | AE14: =SUMIFS(出库流水账!$E:$E,出库流水账!$C:$C,$B14,出库流水账!$B:$B,AD$3) -> 0 | AF14: =SUMIFS(入库流水账!$E:$E,入库流水账!$C:$C,$B14,入库流水账!$B:$B,AF$3) -> 0 | AG14: =SUMIFS(出库流水账!$E:$E,出库流水账!$C:$C,$B14,出库流水账!$B:$B,AF$3) -> 0 | AH14: =SUMIFS(入库流水账!$E:$E,入库流水账!$C:$C,$B14,入库流水账!$B:$B,AH$3) -> 0 | AI14: =SUMIFS(出库流水账!$E:$E,出库流水账!$C:$C,$B14,出库流水账!$B:$B,AH$3) -> 4 | AJ14: =SUMIFS(入库流水账!$E:$E,入库流水账!$C:$C,$B14,入库流水账!$B:$B,AJ$3) -> 24 | AK14: =SUMIFS(出库流水账!$E:$E,出库流水账!$C:$C,$B14,出库流水账!$B:$B,AJ$3) -> 0 | AL14: =SUMIFS(入库流水账!$E:$E,入库流水账!$C:$C,$B14,入库流水账!$B:$B,AL$3) -> 0 | AM14: =SUMIFS(出库流水账!$E:$E,出库流水账!$C:$C,$B14,出库流水账!$B:$B,AL$3) -> 0 | AN14: =SUMIFS(入库流水账!$E:$E,入库流水账!$C:$C,$B14,入库流水账!$B:$B,AN$3) -> 0 | AO14: =SUMIFS(出库流水账!$E:$E,出库流水账!$C:$C,$B14,出库流水账!$B:$B,AN$3) -> 0 | AP14: =SUMIFS(入库流水账!$E:$E,入库流水账!$C:$C,$B14,入库流水账!$B:$B,AP$3) -> 0 | AQ14: =SUMIFS(出库流水账!$E:$E,出库流水账!$C:$C,$B14,出库流水账!$B:$B,AP$3) -> 0 | AR14: =SUMIFS(入库流水账!$E:$E,入库流水账!$C:$C,$B14,入库流水账!$B:$B,AR$3) -> 0 | AS14: =SUMIFS(出库流水账!$E:$E,出库流水账!$C:$C,$B14,出库流水账!$B:$B,AR$3) -> 0 | AT14: =SUMIFS(入库流水账!$E:$E,入库流水账!$C:$C,$B14,入库流水账!$B:$B,AT$3) -> 0 | AU14: =SUMIFS(出库流水账!$E:$E,出库流水账!$C:$C,$B14,出库流水账!$B:$B,AT$3) -> 0 | AV14: =SUMIFS(入库流水账!$E:$E,入库流水账!$C:$C,$B14,入库流水账!$B:$B,AV$3) -> 0 | AW14: =SUMIFS(出库流水账!$E:$E,出库流水账!$C:$C,$B14,出库流水账!$B:$B,AV$3) -> 0 | AX14: =SUMIFS(入库流水账!$E:$E,入库流水账!$C:$C,$B14,入库流水账!$B:$B,AX$3) -> 0 | AY14: =SUMIFS(出库流水账!$E:$E,出库流水账!$C:$C,$B14,出库流水账!$B:$B,AX$3) -> 0 | AZ14: =SUMIFS(入库流水账!$E:$E,入库流水账!$C:$C,$B14,入库流水账!$B:$B,AZ$3) -> 0 | BA14: =SUMIFS(出库流水账!$E:$E,出库流水账!$C:$C,$B14,出库流水账!$B:$B,AZ$3) -> 0 | BB14: =SUMIFS(入库流水账!$E:$E,入库流水账!$C:$C,$B14,入库流水账!$B:$B,BB$3) -> 0 | BC14: =SUMIFS(出库流水账!$E:$E,出库流水账!$C:$C,$B14,出库流水账!$B:$B,BB$3) -> 0 | BD14: =SUMIFS(入库流水账!$E:$E,入库流水账!$C:$C,$B14,入库流水账!$B:$B,BD$3) -> 0 | BE14: =SUMIFS(出库流水账!$E:$E,出库流水账!$C:$C,$B14,出库流水账!$B:$B,BD$3) -> 0 | BF14: =SUMIFS(入库流水账!$E:$E,入库流水账!$C:$C,$B14,入库流水账!$B:$B,BF$3) -> 0 | BG14: =SUMIFS(出库流水账!$E:$E,出库流水账!$C:$C,$B14,出库流水账!$B:$B,BF$3) -> 0 | BH14: =SUMIFS(入库流水账!$E:$E,入库流水账!$C:$C,$B14,入库流水账!$B:$B,BH$3) -> 0 | BI14: =SUMIFS(出库流水账!$E:$E,出库流水账!$C:$C,$B14,出库流水账!$B:$B,BH$3) -> 0 | BJ14: =SUMIFS(入库流水账!$E:$E,入库流水账!$C:$C,$B14,入库流水账!$B:$B,BJ$3) -> 0 | BK14: =SUMIFS(出库流水账!$E:$E,出库流水账!$C:$C,$B14,出库流水账!$B:$B,BJ$3) -> 0 | BL14: =SUMIFS(入库流水账!$E:$E,入库流水账!$C:$C,$B14,入库流水账!$B:$B,BL$3) -> 0 | BM14: =SUMIFS(出库流水账!$E:$E,出库流水账!$C:$C,$B14,出库流水账!$B:$B,BL$3) -> 0 | BN14: =SUMIFS(入库流水账!$E:$E,入库流水账!$C:$C,$B14,入库流水账!$B:$B,BN$3) -> 0 | BO14: =SUMIFS(出库流水账!$E:$E,出库流水账!$C:$C,$B14,出库流水账!$B:$B,BN$3) -> 0 | BP14: =SUMIFS(入库流水账!$E:$E,入库流水账!$C:$C,$B14,入库流水账!$B:$B,BP$3) -> 0 | BQ14: =SUMIFS(出库流水账!$E:$E,出库流水账!$C:$C,$B14,出库流水账!$B:$B,BP$3) -> 0
A15: =ROW()-4 -> 11 | B15: 海之佳紫菜 | C15: =IFERROR(VLOOKUP(B15,产品数据!$B:$D,3,FALSE),"") -> 包 | D15: 8 | E15: =SUMIF($H$4:$BQ$4,$E$2,H15:BQ15) -> 0 | F15: =SUMIF($H$4:$BQ$4,$F$2,H15:BQ15) -> 2 | G15: =D15+E15-F15 -> 6 | H15: =SUMIFS(入库流水账!$E:$E,入库流水账!$C:$C,$B15,入库流水账!$B:$B,H$3) -> 0 | I15: =SUMIFS(出库流水账!$E:$E,出库流水账!$C:$C,$B15,出库流水账!$B:$B,H$3) -> 0 | J15: =SUMIFS(入库流水账!$E:$E,入库流水账!$C:$C,$B15,入库流水账!$B:$B,J$3) -> 0 | K15: =SUMIFS(出库流水账!$E:$E,出库流水账!$C:$C,$B15,出库流水账!$B:$B,J$3) -> 0 | L15: =SUMIFS(入库流水账!$E:$E,入库流水账!$C:$C,$B15,入库流水账!$B:$B,L$3) -> 0 | M15: =SUMIFS(出库流水账!$E:$E,出库流水账!$C:$C,$B15,出库流水账!$B:$B,L$3) -> 0 | N15: =SUMIFS(入库流水账!$E:$E,入库流水账!$C:$C,$B15,入库流水账!$B:$B,N$3) -> 0 | O15: =SUMIFS(出库流水账!$E:$E,出库流水账!$C:$C,$B15,出库流水账!$B:$B,N$3) -> 0 | P15: =SUMIFS(入库流水账!$E:$E,入库流水账!$C:$C,$B15,入库流水账!$B:$B,P$3) -> 0 | Q15: =SUMIFS(出库流水账!$E:$E,出库流水账!$C:$C,$B15,出库流水账!$B:$B,P$3) -> 0 | R15: =SUMIFS(入库流水账!$E:$E,入库流水账!$C:$C,$B15,入库流水账!$B:$B,R$3) -> 0 | S15: =SUMIFS(出库流水账!$E:$E,出库流水账!$C:$C,$B15,出库流水账!$B:$B,R$3) -> 0 | T15: =SUMIFS(入库流水账!$E:$E,入库流水账!$C:$C,$B15,入库流水账!$B:$B,T$3) -> 0 | U15: =SUMIFS(出库流水账!$E:$E,出库流水账!$C:$C,$B15,出库流水账!$B:$B,T$3) -> 0 | V15: =SUMIFS(入库流水账!$E:$E,入库流水账!$C:$C,$B15,入库流水账!$B:$B,V$3) -> 0 | W15: =SUMIFS(出库流水账!$E:$E,出库流水账!$C:$C,$B15,出库流水账!$B:$B,V$3) -> 0 | X15: =SUMIFS(入库流水账!$E:$E,入库流水账!$C:$C,$B15,入库流水账!$B:$B,X$3) -> 0 | Y15: =SUMIFS(出库流水账!$E:$E,出库流水账!$C:$C,$B15,出库流水账!$B:$B,X$3) -> 1 | Z15: =SUMIFS(入库流水账!$E:$E,入库流水账!$C:$C,$B15,入库流水账!$B:$B,Z$3) -> 0 | AA15: =SUMIFS(出库流水账!$E:$E,出库流水账!$C:$C,$B15,出库流水账!$B:$B,Z$3) -> 0 | AB15: =SUMIFS(入库流水账!$E:$E,入库流水账!$C:$C,$B15,入库流水账!$B:$B,AB$3) -> 0 | AC15: =SUMIFS(出库流水账!$E:$E,出库流水账!$C:$C,$B15,出库流水账!$B:$B,AB$3) -> 0 | AD15: =SUMIFS(入库流水账!$E:$E,入库流水账!$C:$C,$B15,入库流水账!$B:$B,AD$3) -> 0 | AE15: =SUMIFS(出库流水账!$E:$E,出库流水账!$C:$C,$B15,出库流水账!$B:$B,AD$3) -> 0 | AF15: =SUMIFS(入库流水账!$E:$E,入库流水账!$C:$C,$B15,入库流水账!$B:$B,AF$3) -> 0 | AG15: =SUMIFS(出库流水账!$E:$E,出库流水账!$C:$C,$B15,出库流水账!$B:$B,AF$3) -> 0 | AH15: =SUMIFS(入库流水账!$E:$E,入库流水账!$C:$C,$B15,入库流水账!$B:$B,AH$3) -> 0 | AI15: =SUMIFS(出库流水账!$E:$E,出库流水账!$C:$C,$B15,出库流水账!$B:$B,AH$3) -> 0 | AJ15: =SUMIFS(入库流水账!$E:$E,入库流水账!$C:$C,$B15,入库流水账!$B:$B,AJ$3) -> 0 | AK15: =SUMIFS(出库流水账!$E:$E,出库流水账!$C:$C,$B15,出库流水账!$B:$B,AJ$3) -> 0 | AL15: =SUMIFS(入库流水账!$E:$E,入库流水账!$C:$C,$B15,入库流水账!$B:$B,AL$3) -> 0 | AM15: =SUMIFS(出库流水账!$E:$E,出库流水账!$C:$C,$B15,出库流水账!$B:$B,AL$3) -> 0 | AN15: =SUMIFS(入库流水账!$E:$E,入库流水账!$C:$C,$B15,入库流水账!$B:$B,AN$3) -> 0 | AO15: =SUMIFS(出库流水账!$E:$E,出库流水账!$C:$C,$B15,出库流水账!$B:$B,AN$3) -> 0 | AP15: =SUMIFS(入库流水账!$E:$E,入库流水账!$C:$C,$B15,入库流水账!$B:$B,AP$3) -> 0 | AQ15: =SUMIFS(出库流水账!$E:$E,出库流水账!$C:$C,$B15,出库流水账!$B:$B,AP$3) -> 0 | AR15: =SUMIFS(入库流水账!$E:$E,入库流水账!$C:$C,$B15,入库流水账!$B:$B,AR$3) -> 0 | AS15: =SUMIFS(出库流水账!$E:$E,出库流水账!$C:$C,$B15,出库流水账!$B:$B,AR$3) -> 0 | AT15: =SUMIFS(入库流水账!$E:$E,入库流水账!$C:$C,$B15,入库流水账!$B:$B,AT$3) -> 0 | AU15: =SUMIFS(出库流水账!$E:$E,出库流水账!$C:$C,$B15,出库流水账!$B:$B,AT$3) -> 0 | AV15: =SUMIFS(入库流水账!$E:$E,入库流水账!$C:$C,$B15,入库流水账!$B:$B,AV$3) -> 0 | AW15: =SUMIFS(出库流水账!$E:$E,出库流水账!$C:$C,$B15,出库流水账!$B:$B,AV$3) -> 0 | AX15: =SUMIFS(入库流水账!$E:$E,入库流水账!$C:$C,$B15,入库流水账!$B:$B,AX$3) -> 0 | AY15: =SUMIFS(出库流水账!$E:$E,出库流水账!$C:$C,$B15,出库流水账!$B:$B,AX$3) -> 0 | AZ15: =SUMIFS(入库流水账!$E:$E,入库流水账!$C:$C,$B15,入库流水账!$B:$B,AZ$3) -> 0 | BA15: =SUMIFS(出库流水账!$E:$E,出库流水账!$C:$C,$B15,出库流水账!$B:$B,AZ$3) -> 1 | BB15: =SUMIFS(入库流水账!$E:$E,入库流水账!$C:$C,$B15,入库流水账!$B:$B,BB$3) -> 0 | BC15: =SUMIFS(出库流水账!$E:$E,出库流水账!$C:$C,$B15,出库流水账!$B:$B,BB$3) -> 0 | BD15: =SUMIFS(入库流水账!$E:$E,入库流水账!$C:$C,$B15,入库流水账!$B:$B,BD$3) -> 0 | BE15: =SUMIFS(出库流水账!$E:$E,出库流水账!$C:$C,$B15,出库流水账!$B:$B,BD$3) -> 0 | BF15: =SUMIFS(入库流水账!$E:$E,入库流水账!$C:$C,$B15,入库流水账!$B:$B,BF$3) -> 0 | BG15: =SUMIFS(出库流水账!$E:$E,出库流水账!$C:$C,$B15,出库流水账!$B:$B,BF$3) -> 0 | BH15: =SUMIFS(入库流水账!$E:$E,入库流水账!$C:$C,$B15,入库流水账!$B:$B,BH$3) -> 0 | BI15: =SUMIFS(出库流水账!$E:$E,出库流水账!$C:$C,$B15,出库流水账!$B:$B,BH$3) -> 0 | BJ15: =SUMIFS(入库流水账!$E:$E,入库流水账!$C:$C,$B15,入库流水账!$B:$B,BJ$3) -> 0 | BK15: =SUMIFS(出库流水账!$E:$E,出库流水账!$C:$C,$B15,出库流水账!$B:$B,BJ$3) -> 0 | BL15: =SUMIFS(入库流水账!$E:$E,入库流水账!$C:$C,$B15,入库流水账!$B:$B,BL$3) -> 0 | BM15: =SUMIFS(出库流水账!$E:$E,出库流水账!$C:$C,$B15,出库流水账!$B:$B,BL$3) -> 0 | BN15: =SUMIFS(入库流水账!$E:$E,入库流水账!$C:$C,$B15,入库流水账!$B:$B,BN$3) -> 0 | BO15: =SUMIFS(出库流水账!$E:$E,出库流水账!$C:$C,$B15,出库流水账!$B:$B,BN$3) -> 0 | BP15: =SUMIFS(入库流水账!$E:$E,入库流水账!$C:$C,$B15,入库流水账!$B:$B,BP$3) -> 0 | BQ15: =SUMIFS(出库流水账!$E:$E,出库流水账!$C:$C,$B15,出库流水账!$B:$B,BP$3) -> 0
A16: =ROW()-4 -> 12 | B16: 滇玉小米辣 | C16: =IFERROR(VLOOKUP(B16,产品数据!$B:$D,3,FALSE),"") -> 包 | D16: 7 | E16: =SUMIF($H$4:$BQ$4,$E$2,H16:BQ16) -> 30 | F16: =SUMIF($H$4:$BQ$4,$F$2,H16:BQ16) -> 5 | G16: =D16+E16-F16 -> 32 | H16: =SUMIFS(入库流水账!$E:$E,入库流水账!$C:$C,$B16,入库流水账!$B:$B,H$3) -> 0 | I16: =SUMIFS(出库流水账!$E:$E,出库流水账!$C:$C,$B16,出库流水账!$B:$B,H$3) -> 0 | J16: =SUMIFS(入库流水账!$E:$E,入库流水账!$C:$C,$B16,入库流水账!$B:$B,J$3) -> 0 | K16: =SUMIFS(出库流水账!$E:$E,出库流水账!$C:$C,$B16,出库流水账!$B:$B,J$3) -> 0 | L16: =SUMIFS(入库流水账!$E:$E,入库流水账!$C:$C,$B16,入库流水账!$B:$B,L$3) -> 0 | M16: =SUMIFS(出库流水账!$E:$E,出库流水账!$C:$C,$B16,出库流水账!$B:$B,L$3) -> 0 | N16: =SUMIFS(入库流水账!$E:$E,入库流水账!$C:$C,$B16,入库流水账!$B:$B,N$3) -> 0 | O16: =SUMIFS(出库流水账!$E:$E,出库流水账!$C:$C,$B16,出库流水账!$B:$B,N$3) -> 0 | P16: =SUMIFS(入库流水账!$E:$E,入库流水账!$C:$C,$B16,入库流水账!$B:$B,P$3) -> 0 | Q16: =SUMIFS(出库流水账!$E:$E,出库流水账!$C:$C,$B16,出库流水账!$B:$B,P$3) -> 2 | R16: =SUMIFS(入库流水账!$E:$E,入库流水账!$C:$C,$B16,入库流水账!$B:$B,R$3) -> 0 | S16: =SUMIFS(出库流水账!$E:$E,出库流水账!$C:$C,$B16,出库流水账!$B:$B,R$3) -> 1 | T16: =SUMIFS(入库流水账!$E:$E,入库流水账!$C:$C,$B16,入库流水账!$B:$B,T$3) -> 0 | U16: =SUMIFS(出库流水账!$E:$E,出库流水账!$C:$C,$B16,出库流水账!$B:$B,T$3) -> 0 | V16: =SUMIFS(入库流水账!$E:$E,入库流水账!$C:$C,$B16,入库流水账!$B:$B,V$3) -> 0 | W16: =SUMIFS(出库流水账!$E:$E,出库流水账!$C:$C,$B16,出库流水账!$B:$B,V$3) -> 0 | X16: =SUMIFS(入库流水账!$E:$E,入库流水账!$C:$C,$B16,入库流水账!$B:$B,X$3) -> 0 | Y16: =SUMIFS(出库流水账!$E:$E,出库流水账!$C:$C,$B16,出库流水账!$B:$B,X$3) -> 0 | Z16: =SUMIFS(入库流水账!$E:$E,入库流水账!$C:$C,$B16,入库流水账!$B:$B,Z$3) -> 0 | AA16: =SUMIFS(出库流水账!$E:$E,出库流水账!$C:$C,$B16,出库流水账!$B:$B,Z$3) -> 0 | AB16: =SUMIFS(入库流水账!$E:$E,入库流水账!$C:$C,$B16,入库流水账!$B:$B,AB$3) -> 0 | AC16: =SUMIFS(出库流水账!$E:$E,出库流水账!$C:$C,$B16,出库流水账!$B:$B,AB$3) -> 0 | AD16: =SUMIFS(入库流水账!$E:$E,入库流水账!$C:$C,$B16,入库流水账!$B:$B,AD$3) -> 30 | AE16: =SUMIFS(出库流水账!$E:$E,出库流水账!$C:$C,$B16,出库流水账!$B:$B,AD$3) -> 0 | AF16: =SUMIFS(入库流水账!$E:$E,入库流水账!$C:$C,$B16,入库流水账!$B:$B,AF$3) -> 0 | AG16: =SUMIFS(出库流水账!$E:$E,出库流水账!$C:$C,$B16,出库流水账!$B:$B,AF$3) -> 0 | AH16: =SUMIFS(入库流水账!$E:$E,入库流水账!$C:$C,$B16,入库流水账!$B:$B,AH$3) -> 0 | AI16: =SUMIFS(出库流水账!$E:$E,出库流水账!$C:$C,$B16,出库流水账!$B:$B,AH$3) -> 0 | AJ16: =SUMIFS(入库流水账!$E:$E,入库流水账!$C:$C,$B16,入库流水账!$B:$B,AJ$3) -> 0 | AK16: =SUMIFS(出库流水账!$E:$E,出库流水账!$C:$C,$B16,出库流水账!$B:$B,AJ$3) -> 1 | AL16: =SUMIFS(入库流水账!$E:$E,入库流水账!$C:$C,$B16,入库流水账!$B:$B,AL$3) -> 0 | AM16: =SUMIFS(出库流水账!$E:$E,出库流水账!$C:$C,$B16,出库流水账!$B:$B,AL$3) -> 0 | AN16: =SUMIFS(入库流水账!$E:$E,入库流水账!$C:$C,$B16,入库流水账!$B:$B,AN$3) -> 0 | AO16: =SUMIFS(出库流水账!$E:$E,出库流水账!$C:$C,$B16,出库流水账!$B:$B,AN$3) -> 0 | AP16: =SUMIFS(入库流水账!$E:$E,入库流水账!$C:$C,$B16,入库流水账!$B:$B,AP$3) -> 0 | AQ16: =SUMIFS(出库流水账!$E:$E,出库流水账!$C:$C,$B16,出库流水账!$B:$B,AP$3) -> 0 | AR16: =SUMIFS(入库流水账!$E:$E,入库流水账!$C:$C,$B16,入库流水账!$B:$B,AR$3) -> 0 | AS16: =SUMIFS(出库流水账!$E:$E,出库流水账!$C:$C,$B16,出库流水账!$B:$B,AR$3) -> 0 | AT16: =SUMIFS(入库流水账!$E:$E,入库流水账!$C:$C,$B16,入库流水账!$B:$B,AT$3) -> 0 | AU16: =SUMIFS(出库流水账!$E:$E,出库流水账!$C:$C,$B16,出库流水账!$B:$B,AT$3) -> 0 | AV16: =SUMIFS(入库流水账!$E:$E,入库流水账!$C:$C,$B16,入库流水账!$B:$B,AV$3) -> 0 | AW16: =SUMIFS(出库流水账!$E:$E,出库流水账!$C:$C,$B16,出库流水账!$B:$B,AV$3) -> 0 | AX16: =SUMIFS(入库流水账!$E:$E,入库流水账!$C:$C,$B16,入库流水账!$B:$B,AX$3) -> 0 | AY16: =SUMIFS(出库流水账!$E:$E,出库流水账!$C:$C,$B16,出库流水账!$B:$B,AX$3) -> 0 | AZ16: =SUMIFS(入库流水账!$E:$E,入库流水账!$C:$C,$B16,入库流水账!$B:$B,AZ$3) -> 0 | BA16: =SUMIFS(出库流水账!$E:$E,出库流水账!$C:$C,$B16,出库流水账!$B:$B,AZ$3) -> 0 | BB16: =SUMIFS(入库流水账!$E:$E,入库流水账!$C:$C,$B16,入库流水账!$B:$B,BB$3) -> 0 | BC16: =SUMIFS(出库流水账!$E:$E,出库流水账!$C:$C,$B16,出库流水账!$B:$B,BB$3) -> 0 | BD16: =SUMIFS(入库流水账!$E:$E,入库流水账!$C:$C,$B16,入库流水账!$B:$B,BD$3) -> 0 | BE16: =SUMIFS(出库流水账!$E:$E,出库流水账!$C:$C,$B16,出库流水账!$B:$B,BD$3) -> 0 | BF16: =SUMIFS(入库流水账!$E:$E,入库流水账!$C:$C,$B16,入库流水账!$B:$B,BF$3) -> 0 | BG16: =SUMIFS(出库流水账!$E:$E,出库流水账!$C:$C,$B16,出库流水账!$B:$B,BF$3) -> 0 | BH16: =SUMIFS(入库流水账!$E:$E,入库流水账!$C:$C,$B16,入库流水账!$B:$B,BH$3) -> 0 | BI16: =SUMIFS(出库流水账!$E:$E,出库流水账!$C:$C,$B16,出库流水账!$B:$B,BH$3) -> 1 | BJ16: =SUMIFS(入库流水账!$E:$E,入库流水账!$C:$C,$B16,入库流水账!$B:$B,BJ$3) -> 0 | BK16: =SUMIFS(出库流水账!$E:$E,出库流水账!$C:$C,$B16,出库流水账!$B:$B,BJ$3) -> 0 | BL16: =SUMIFS(入库流水账!$E:$E,入库流水账!$C:$C,$B16,入库流水账!$B:$B,BL$3) -> 0 | BM16: =SUMIFS(出库流水账!$E:$E,出库流水账!$C:$C,$B16,出库流水账!$B:$B,BL$3) -> 0 | BN16: =SUMIFS(入库流水账!$E:$E,入库流水账!$C:$C,$B16,入库流水账!$B:$B,BN$3) -> 0 | BO16: =SUMIFS(出库流水账!$E:$E,出库流水账!$C:$C,$B16,出库流水账!$B:$B,BN$3) -> 0 | BP16: =SUMIFS(入库流水账!$E:$E,入库流水账!$C:$C,$B16,入库流水账!$B:$B,BP$3) -> 0 | BQ16: =SUMIFS(出库流水账!$E:$E,出库流水账!$C:$C,$B16,出库流水账!$B:$B,BP$3) -> 0
A17: =ROW()-4 -> 13 | B17: 雪涛加碘精制盐 | C17: =IFERROR(VLOOKUP(B17,产品数据!$B:$D,3,FALSE),"") -> 包 | D17: ='[2]米油调味品台账表 12月 '!G18 -> 0 | E17: =SUMIF($H$4:$BQ$4,$E$2,H17:BQ17) -> 0 | F17: =SUMIF($H$4:$BQ$4,$F$2,H17:BQ17) -> 0 | G17: =D17+E17-F17 -> 0 | H17: =SUMIFS(入库流水账!$E:$E,入库流水账!$C:$C,$B17,入库流水账!$B:$B,H$3) -> 0 | I17: =SUMIFS(出库流水账!$E:$E,出库流水账!$C:$C,$B17,出库流水账!$B:$B,H$3) -> 0 | J17: =SUMIFS(入库流水账!$E:$E,入库流水账!$C:$C,$B17,入库流水账!$B:$B,J$3) -> 0 | K17: =SUMIFS(出库流水账!$E:$E,出库流水账!$C:$C,$B17,出库流水账!$B:$B,J$3) -> 0 | L17: =SUMIFS(入库流水账!$E:$E,入库流水账!$C:$C,$B17,入库流水账!$B:$B,L$3) -> 0 | M17: =SUMIFS(出库流水账!$E:$E,出库流水账!$C:$C,$B17,出库流水账!$B:$B,L$3) -> 0 | N17: =SUMIFS(入库流水账!$E:$E,入库流水账!$C:$C,$B17,入库流水账!$B:$B,N$3) -> 0 | O17: =SUMIFS(出库流水账!$E:$E,出库流水账!$C:$C,$B17,出库流水账!$B:$B,N$3) -> 0 | P17: =SUMIFS(入库流水账!$E:$E,入库流水账!$C:$C,$B17,入库流水账!$B:$B,P$3) -> 0 | Q17: =SUMIFS(出库流水账!$E:$E,出库流水账!$C:$C,$B17,出库流水账!$B:$B,P$3) -> 0 | R17: =SUMIFS(入库流水账!$E:$E,入库流水账!$C:$C,$B17,入库流水账!$B:$B,R$3) -> 0 | S17: =SUMIFS(出库流水账!$E:$E,出库流水账!$C:$C,$B17,出库流水账!$B:$B,R$3) -> 0 | T17: =SUMIFS(入库流水账!$E:$E,入库流水账!$C:$C,$B17,入库流水账!$B:$B,T$3) -> 0 | U17: =SUMIFS(出库流水账!$E:$E,出库流水账!$C:$C,$B17,出库流水账!$B:$B,T$3) -> 0 | V17: =SUMIFS(入库流水账!$E:$E,入库流水账!$C:$C,$B17,入库流水账!$B:$B,V$3) -> 0 | W17: =SUMIFS(出库流水账!$E:$E,出库流水账!$C:$C,$B17,出库流水账!$B:$B,V$3) -> 0 | X17: =SUMIFS(入库流水账!$E:$E,入库流水账!$C:$C,$B17,入库流水账!$B:$B,X$3) -> 0 | Y17: =SUMIFS(出库流水账!$E:$E,出库流水账!$C:$C,$B17,出库流水账!$B:$B,X$3) -> 0 | Z17: =SUMIFS(入库流水账!$E:$E,入库流水账!$C:$C,$B17,入库流水账!$B:$B,Z$3) -> 0 | AA17: =SUMIFS(出库流水账!$E:$E,出库流水账!$C:$C,$B17,出库流水账!$B:$B,Z$3) -> 0 | AB17: =SUMIFS(入库流水账!$E:$E,入库流水账!$C:$C,$B17,入库流水账!$B:$B,AB$3) -> 0 | AC17: =SUMIFS(出库流水账!$E:$E,出库流水账!$C:$C,$B17,出库流水账!$B:$B,AB$3) -> 0 | AD17: =SUMIFS(入库流水账!$E:$E,入库流水账!$C:$C,$B17,入库流水账!$B:$B,AD$3) -> 0 | AE17: =SUMIFS(出库流水账!$E:$E,出库流水账!$C:$C,$B17,出库流水账!$B:$B,AD$3) -> 0 | AF17: =SUMIFS(入库流水账!$E:$E,入库流水账!$C:$C,$B17,入库流水账!$B:$B,AF$3) -> 0 | AG17: =SUMIFS(出库流水账!$E:$E,出库流水账!$C:$C,$B17,出库流水账!$B:$B,AF$3) -> 0 | AH17: =SUMIFS(入库流水账!$E:$E,入库流水账!$C:$C,$B17,入库流水账!$B:$B,AH$3) -> 0 | AI17: =SUMIFS(出库流水账!$E:$E,出库流水账!$C:$C,$B17,出库流水账!$B:$B,AH$3) -> 0 | AJ17: =SUMIFS(入库流水账!$E:$E,入库流水账!$C:$C,$B17,入库流水账!$B:$B,AJ$3) -> 0 | AK17: =SUMIFS(出库流水账!$E:$E,出库流水账!$C:$C,$B17,出库流水账!$B:$B,AJ$3) -> 0 | AL17: =SUMIFS(入库流水账!$E:$E,入库流水账!$C:$C,$B17,入库流水账!$B:$B,AL$3) -> 0 | AM17: =SUMIFS(出库流水账!$E:$E,出库流水账!$C:$C,$B17,出库流水账!$B:$B,AL$3) -> 0 | AN17: =SUMIFS(入库流水账!$E:$E,入库流水账!$C:$C,$B17,入库流水账!$B:$B,AN$3) -> 0 | AO17: =SUMIFS(出库流水账!$E:$E,出库流水账!$C:$C,$B17,出库流水账!$B:$B,AN$3) -> 0 | AP17: =SUMIFS(入库流水账!$E:$E,入库流水账!$C:$C,$B17,入库流水账!$B:$B,AP$3) -> 0 | AQ17: =SUMIFS(出库流水账!$E:$E,出库流水账!$C:$C,$B17,出库流水账!$B:$B,AP$3) -> 0 | AR17: =SUMIFS(入库流水账!$E:$E,入库流水账!$C:$C,$B17,入库流水账!$B:$B,AR$3) -> 0 | AS17: =SUMIFS(出库流水账!$E:$E,出库流水账!$C:$C,$B17,出库流水账!$B:$B,AR$3) -> 0 | AT17: =SUMIFS(入库流水账!$E:$E,入库流水账!$C:$C,$B17,入库流水账!$B:$B,AT$3) -> 0 | AU17: =SUMIFS(出库流水账!$E:$E,出库流水账!$C:$C,$B17,出库流水账!$B:$B,AT$3) -> 0 | AV17: =SUMIFS(入库流水账!$E:$E,入库流水账!$C:$C,$B17,入库流水账!$B:$B,AV$3) -> 0 | AW17: =SUMIFS(出库流水账!$E:$E,出库流水账!$C:$C,$B17,出库流水账!$B:$B,AV$3) -> 0 | AX17: =SUMIFS(入库流水账!$E:$E,入库流水账!$C:$C,$B17,入库流水账!$B:$B,AX$3) -> 0 | AY17: =SUMIFS(出库流水账!$E:$E,出库流水账!$C:$C,$B17,出库流水账!$B:$B,AX$3) -> 0 | AZ17: =SUMIFS(入库流水账!$E:$E,入库流水账!$C:$C,$B17,入库流水账!$B:$B,AZ$3) -> 0 | BA17: =SUMIFS(出库流水账!$E:$E,出库流水账!$C:$C,$B17,出库流水账!$B:$B,AZ$3) -> 0 | BB17: =SUMIFS(入库流水账!$E:$E,入库流水账!$C:$C,$B17,入库流水账!$B:$B,BB$3) -> 0 | BC17: =SUMIFS(出库流水账!$E:$E,出库流水账!$C:$C,$B17,出库流水账!$B:$B,BB$3) -> 0 | BD17: =SUMIFS(入库流水账!$E:$E,入库流水账!$C:$C,$B17,入库流水账!$B:$B,BD$3) -> 0 | BE17: =SUMIFS(出库流水账!$E:$E,出库流水账!$C:$C,$B17,出库流水账!$B:$B,BD$3) -> 0 | BF17: =SUMIFS(入库流水账!$E:$E,入库流水账!$C:$C,$B17,入库流水账!$B:$B,BF$3) -> 0 | BG17: =SUMIFS(出库流水账!$E:$E,出库流水账!$C:$C,$B17,出库流水账!$B:$B,BF$3) -> 0 | BH17: =SUMIFS(入库流水账!$E:$E,入库流水账!$C:$C,$B17,入库流水账!$B:$B,BH$3) -> 0 | BI17: =SUMIFS(出库流水账!$E:$E,出库流水账!$C:$C,$B17,出库流水账!$B:$B,BH$3) -> 0 | BJ17: =SUMIFS(入库流水账!$E:$E,入库流水账!$C:$C,$B17,入库流水账!$B:$B,BJ$3) -> 0 | BK17: =SUMIFS(出库流水账!$E:$E,出库流水账!$C:$C,$B17,出库流水账!$B:$B,BJ$3) -> 0 | BL17: =SUMIFS(入库流水账!$E:$E,入库流水账!$C:$C,$B17,入库流水账!$B:$B,BL$3) -> 0 | BM17: =SUMIFS(出库流水账!$E:$E,出库流水账!$C:$C,$B17,出库流水账!$B:$B,BL$3) -> 0 | BN17: =SUMIFS(入库流水账!$E:$E,入库流水账!$C:$C,$B17,入库流水账!$B:$B,BN$3) -> 0 | BO17: =SUMIFS(出库流水账!$E:$E,出库流水账!$C:$C,$B17,出库流水账!$B:$B,BN$3) -> 0 | BP17: =SUMIFS(入库流水账!$E:$E,入库流水账!$C:$C,$B17,入库流水账!$B:$B,BP$3) -> 0 | BQ17: =SUMIFS(出库流水账!$E:$E,出库流水账!$C:$C,$B17,出库流水账!$B:$B,BP$3) -> 0
